Workbook

Sheet Menu
C1: Cocoa Grindings Outlook
G5: ECA | L5: ECA : Non German Grind | Q5: Germany Grind
G8: NCA
G11: CAA | L11: CAA : Non Malaysian Grind | Q11: Malaysian Grind
G14: Ivory Coast
G17: Brazil
G20: Cocoa Grinds | Q3 25/26
H21: YoY | I21: QoQ | J21: YTD | K21: Q3 | 25/26
G22: ECA | H22: =ECA!S30 -> -0.046406761 | I22: =ECA!S44 -> -0.029239479 | J22: =ECA!Z16 -> -0.043960457 | K22: =ECA!C45 -> 316366
G23: NCA | H23: =NCA!S29 -> 0.076513032 | I23: =NCA!S43 -> 0.033670478 | J23: =NCA!AA16 -> 0.012572085 | K23: =NCA!C45 -> 109659
G24: CAA | H24: =CAA!S29 -> 0.25068757 | I24: =CAA!S43 -> 0.0051140253 | J24: =CAA!AA16 -> 0.12685226 | K24: =CAA!C45 -> 224646
G25: IVC | H25: =IVC!S29 -> 0.235305 | I25: =IVC!S43 -> -0.092741101 | J25: =IVC!AA16 -> 0.097960232 | K25: =IVC!C45 -> 153520
G26: BR | H26: =BR!S29 -> 0.0861477 | I26: =BR!S43 -> -0.038746984 | J26: =BR!AA16 -> -0.026982409 | K26: =BR!C45 -> 52197
G27: Total | H27: =TOTAL!X29 -> 0.086677858 | I27: =TOTAL!X43 -> -0.025723579 | J27: =TOTAL!AF16 -> -0.010549405 | K27: =TOTAL!C45 -> 856388

Sheet TOTAL
A1: All Reported Grind : ECA + CAA + NCA + IVC (Gepex) + BR
AD3: =COUNT(V16:Y16) -> 3 | AE3: =OFFSET(U6,0,$AD$3,1,1) -> Q3
V5: 1 | W5: 2 | X5: 3 | Y5: 4
B6: Quarter | C6: Total | D6: ECA | E6: CAA | F6: NCA | G6: IVC | H6: BR | I6: CAA / ECA | V6: Q1 | W6: Q2 | X6: Q3 | Y6: Q4 | Z6: Q1-Q4 | AA6: % | AD6: Crop Year | AE6: =_xlfn.CONCAT("YTD (Q1 to ",AE3,")") -> YTD (Q1 to Q3) | AF6: % | AJ6: Q1 | AK6: Q2 | AL6: Q3 | AM6: Q4
B7: Q1 | 16/17 | C7: =SUM(D7:H7) -> 822589 | D7: =IF(ECA!C7=0,NA(),ECA!C7) -> 339741 | E7: =IF(CAA!C7=0,NA(),CAA!C7) -> 177450 | F7: =IF(NCA!C7=0,NA(),NCA!C7) -> 120152 | G7: =IF(IVC!C7=0,NA(),IVC!C7) -> 127000 | H7: =IF(BR!C7=0,NA(),BR!C7) -> 58246 | I7: =E7/D7 -> 0.52230964 | U7: 16/17 | V7: =C7 -> 822589 | W7: =C8 -> 822589 | X7: =C9 -> 798014 | Y7: =C10 -> 850839 | Z7: =SUM(V7:Y7) -> 3294031 | AD7: 16/17 | AE7: =SUM(OFFSET(V7,0,0,1,$AD$3)) -> 2443192 | AI7: 2017 | AJ7: =V7 -> 822589 | AK7: =AJ7+W7 -> 1645178 | AL7: =AK7+X7 -> 2443192 | AM7: =AL7+Y7 -> 3294031
B8: Q2 | 16/17 | C8: =SUM(D8:H8) -> 822589 | D8: =IF(ECA!C8=0,NA(),ECA!C8) -> 339741 | E8: =IF(CAA!C8=0,NA(),CAA!C8) -> 177450 | F8: =IF(NCA!C8=0,NA(),NCA!C8) -> 120152 | G8: =IF(IVC!C8=0,NA(),IVC!C8) -> 127000 | H8: =IF(BR!C8=0,NA(),BR!C8) -> 58246 | I8: =E8/D8 -> 0.52230964 | U8: 17/18 | V8: =C11 -> 850107 | W8: =C12 -> 855759 | X8: =C13 -> 837530 | Y8: =C14 -> 874536 | Z8: =SUM(V8:Y8) -> 3417932 | AA8: =Z8/Z7-1 -> 0.037613793 | AD8: 17/18 | AE8: =SUM(OFFSET(V8,0,0,1,$AD$3)) -> 2543396 | AF8: =AE8/AE7-1 -> 0.041013559 | AI8: 2018 | AJ8: =V8 -> 850107 | AK8: =AJ8+W8 -> 1705866 | AL8: =AK8+X8 -> 2543396 | AM8: =AL8+Y8 -> 3417932
B9: Q3 | 16/17 | C9: =SUM(D9:H9) -> 798014 | D9: =IF(ECA!C9=0,NA(),ECA!C9) -> 331970 | E9: =IF(CAA!C9=0,NA(),CAA!C9) -> 160878 | F9: =IF(NCA!C9=0,NA(),NCA!C9) -> 123125 | G9: =IF(IVC!C9=0,NA(),IVC!C9) -> 127000 | H9: =IF(BR!C9=0,NA(),BR!C9) -> 55041 | I9: =E9/D9 -> 0.48461608 | U9: 18/19 | V9: =C15 -> 881322 | W9: =C16 -> 890013 | X9: =C17 -> 882822 | Y9: =C18 -> 910769 | Z9: =SUM(V9:Y9) -> 3564926 | AA9: =Z9/Z8-1 -> 0.043006707 | AD9: 18/19 | AE9: =SUM(OFFSET(V9,0,0,1,$AD$3)) -> 2654157 | AF9: =AE9/AE8-1 -> 0.043548468 | AI9: 2019 | AJ9: =V9 -> 881322 | AK9: =AJ9+W9 -> 1771335 | AL9: =AK9+X9 -> 2654157 | AM9: =AL9+Y9 -> 3564926
B10: Q4 | 16/17 | C10: =SUM(D10:H10) -> 850839 | D10: =IF(ECA!C10=0,NA(),ECA!C10) -> 353544 | E10: =IF(CAA!C10=0,NA(),CAA!C10) -> 189407 | F10: =IF(NCA!C10=0,NA(),NCA!C10) -> 125323 | G10: =IF(IVC!C10=0,NA(),IVC!C10) -> 128000 | H10: =IF(BR!C10=0,NA(),BR!C10) -> 54565 | I10: =E10/D10 -> 0.53573813 | U10: 19/20 | V10: =C19 -> 894393 | W10: =C20 -> 891865 | X10: =C21 -> 812601 | Y10: =C22 -> 860903 | Z10: =SUM(V10:Y10) -> 3459762 | AA10: =Z10/Z9-1 -> -0.029499631 | AD10: 19/20 | AE10: =SUM(OFFSET(V10,0,0,1,$AD$3)) -> 2598859 | AF10: =AE10/AE9-1 -> -0.020834487 | AI10: 2020 | AJ10: =V10 -> 894393 | AK10: =AJ10+W10 -> 1786258 | AL10: =AK10+X10 -> 2598859 | AM10: =AL10+Y10 -> 3459762
B11: Q1 | 17/18 | C11: =SUM(D11:H11) -> 850107 | D11: =IF(ECA!C11=0,NA(),ECA!C11) -> 353286 | E11: =IF(CAA!C11=0,NA(),CAA!C11) -> 196476 | F11: =IF(NCA!C11=0,NA(),NCA!C11) -> 116080 | G11: =IF(IVC!C11=0,NA(),IVC!C11) -> 124000 | H11: =IF(BR!C11=0,NA(),BR!C11) -> 60265 | I11: =E11/D11 -> 0.55613865 | U11: 20/21 | V11: =C23 -> 890571 | W11: =C24 -> 900134 | X11: =C25 -> 865508 | Y11: =C26 -> 920397 | Z11: =SUM(V11:Y11) -> 3576610 | AA11: =Z11/Z10-1 -> 0.033773421 | AD11: 20/21 | AE11: =SUM(OFFSET(V11,0,0,1,$AD$3)) -> 2656213 | AF11: =AE11/AE10-1 -> 0.022068916 | AI11: 2021 | AJ11: =V11 -> 890571 | AK11: =AJ11+W11 -> 1790705 | AL11: =AK11+X11 -> 2656213 | AM11: =AL11+Y11 -> 3576610
B12: Q2 | 17/18 | C12: =SUM(D12:H12) -> 855759 | D12: =IF(ECA!C12=0,NA(),ECA!C12) -> 358432 | E12: =IF(CAA!C12=0,NA(),CAA!C12) -> 190244 | F12: =IF(NCA!C12=0,NA(),NCA!C12) -> 118778 | G12: =IF(IVC!C12=0,NA(),IVC!C12) -> 130000 | H12: =IF(BR!C12=0,NA(),BR!C12) -> 58305 | I12: =E12/D12 -> 0.53076734 | U12: 21/22 | V12: =C27 -> 929248 | W12: =C28 -> 912398 | X12: =C29 -> 916242 | Y12: =C30 -> 950094 | Z12: =SUM(V12:Y12) -> 3707982 | AA12: =Z12/Z11-1 -> 0.036730871 | AD12: 21/22 | AE12: =SUM(OFFSET(V12,0,0,1,$AD$3)) -> 2757888 | AF12: =AE12/AE11-1 -> 0.03827818 | AI12: 2022 | AJ12: =V12 -> 929248 | AK12: =AJ12+W12 -> 1841646 | AL12: =AK12+X12 -> 2757888 | AM12: =AL12+Y12 -> 3707982
B13: Q3 | 17/18 | C13: =SUM(D13:H13) -> 837530 | D13: =IF(ECA!C13=0,NA(),ECA!C13) -> 356109 | E13: =IF(CAA!C13=0,NA(),CAA!C13) -> 185394 | F13: =IF(NCA!C13=0,NA(),NCA!C13) -> 119301 | G13: =IF(IVC!C13=0,NA(),IVC!C13) -> 125000 | H13: =IF(BR!C13=0,NA(),BR!C13) -> 51726 | I13: =E13/D13 -> 0.52061026 | U13: 22/23 | V13: =IF(C31=0,"",C31) -> 930529 | W13: =IF(C32=0,"",C32) -> 960085 | X13: =IF(C33=0,"",C33) -> 884179 | Y13: =IF(C34=0,NA(),C34) -> 922671 | Z13: =SUM(V13:Y13) -> 3697464 | AA13: =Z13/Z12-1 -> -0.0028365833 | AD13: 22/23 | AE13: =SUM(OFFSET(V13,0,0,1,$AD$3)) -> 2774793 | AF13: =AE13/AE12-1 -> 0.0061296905 | AI13: 2023 | AJ13: =V13 -> 930529 | AK13: =AJ13+W13 -> 1890614 | AL13: =AK13+X13 -> 2774793 | AM13: =AL13+Y13 -> 3697464
B14: Q4 | 17/18 | C14: =SUM(D14:H14) -> 874536 | D14: =IF(ECA!C14=0,NA(),ECA!C14) -> 363122 | E14: =IF(CAA!C14=0,NA(),CAA!C14) -> 196418 | F14: =IF(NCA!C14=0,NA(),NCA!C14) -> 128494 | G14: =IF(IVC!C14=0,NA(),IVC!C14) -> 126347 | H14: =IF(BR!C14=0,NA(),BR!C14) -> 60155 | I14: =E14/D14 -> 0.54091462 | U14: 23/24 | V14: =IF(C35=0,"",C35) -> 898937 | W14: =C36 -> 935533 | X14: =IF(C37=0,"",C37) -> 862065 | Y14: =C38 -> 913855 | Z14: =SUM(V14:Y14) -> 3610390 | AA14: =Z14/Z13-1 -> -0.023549655 | AD14: 23/24 | AE14: =SUM(OFFSET(V14,0,0,1,$AD$3)) -> 2696535 | AF14: =AE14/AE13-1 -> -0.028203185 | AI14: 2024 | AJ14: =V14 -> 898937
B15: Q1 | 18/19 | C15: =SUM(D15:H15) -> 881322 | D15: =IF(ECA!C15=0,NA(),ECA!C15) -> 359103 | E15: =IF(CAA!C15=0,NA(),CAA!C15) -> 208900 | F15: =IF(NCA!C15=0,NA(),NCA!C15) -> 117222 | G15: =IF(IVC!C15=0,NA(),IVC!C15) -> 135510 | H15: =IF(BR!C15=0,NA(),BR!C15) -> 60587 | I15: =E15/D15 -> 0.58172725 | U15: 24/25 | V15: =C39 -> 894012 | W15: =C40 -> 905164 | X15: =C41 -> 788079 | Y15: =C42 -> 794361 | Z15: =SUM(V15:Y15) -> 3381616 | AA15: =Z15/Z14-1 -> -0.063365454 | AD15: 24/25 | AE15: =SUM(OFFSET(V15,0,0,1,$AD$3)) -> 2587255 | AF15: =AE15/AE14-1 -> -0.040526083
B16: Q2 | 18/19 | C16: =SUM(D16:H16) -> 890013 | D16: =IF(ECA!C16=0,NA(),ECA!C16) -> 370359 | E16: =IF(CAA!C16=0,NA(),CAA!C16) -> 208388 | F16: =IF(NCA!C16=0,NA(),NCA!C16) -> 121801 | G16: =IF(IVC!C16=0,NA(),IVC!C16) -> 133000 | H16: =IF(BR!C16=0,NA(),BR!C16) -> 56465 | I16: =E16/D16 -> 0.56266487 | U16: 25/26 | V16: =C43 -> 824574 | W16: =C44 -> 878999 | X16: =C45 -> 856388 | AD16: 25/26 | AE16: =SUM(OFFSET(V16,0,0,1,$AD$3)) -> 2559961 | AF16: =AE16/AE15-1 -> -0.010549405
B17: Q3 | 18/19 | C17: =SUM(D17:H17) -> 882822 | D17: =IF(ECA!C17=0,NA(),ECA!C17) -> 344890 | E17: =IF(CAA!C17=0,NA(),CAA!C17) -> 215574 | F17: =IF(NCA!C17=0,NA(),NCA!C17) -> 124050 | G17: =IF(IVC!C17=0,NA(),IVC!C17) -> 139000 | H17: =IF(BR!C17=0,NA(),BR!C17) -> 59308 | I17: =E17/D17 -> 0.62505147
B18: Q4 | 18/19 | C18: =SUM(D18:H18) -> 910769 | D18: =IF(ECA!C18=0,NA(),ECA!C18) -> 362940 | E18: =IF(CAA!C18=0,NA(),CAA!C18) -> 225356 | F18: =IF(NCA!C18=0,NA(),NCA!C18) -> 123208 | G18: =IF(IVC!C18=0,NA(),IVC!C18) -> 140473 | H18: =IF(BR!C18=0,NA(),BR!C18) -> 58792 | I18: =E18/D18 -> 0.62091806 | U18: YoY Change | AD18: Choose Quarter | AF18: Q3
B19: Q1 | 19/20 | C19: =SUM(D19:H19) -> 894393 | D19: =IF(ECA!C19=0,NA(),ECA!C19) -> 355201 | E19: =IF(CAA!C19=0,NA(),CAA!C19) -> 227013 | F19: =IF(NCA!C19=0,NA(),NCA!C19) -> 110371 | G19: =IF(IVC!C19=0,NA(),IVC!C19) -> 144314 | H19: =IF(BR!C19=0,NA(),BR!C19) -> 57494 | I19: =E19/D19 -> 0.63911138 | V19: Q1 | W19: Q2 | X19: Q3 | Y19: Q4
B20: Q2 | 19/20 | C20: =SUM(D20:H20) -> 891865 | D20: =IF(ECA!C20=0,NA(),ECA!C20) -> 368934 | E20: =IF(CAA!C20=0,NA(),CAA!C20) -> 207356 | F20: =IF(NCA!C20=0,NA(),NCA!C20) -> 115591 | G20: =IF(IVC!C20=0,NA(),IVC!C20) -> 139821 | H20: =IF(BR!C20=0,NA(),BR!C20) -> 60163 | I20: =E20/D20 -> 0.56204091 | U20: 16/17
B21: Q3 | 19/20 | C21: =SUM(D21:H21) -> 812601 | D21: =IF(ECA!C21=0,NA(),ECA!C21) -> 314108 | E21: =IF(CAA!C21=0,NA(),CAA!C21) -> 202674 | F21: =IF(NCA!C21=0,NA(),NCA!C21) -> 110776 | G21: =IF(IVC!C21=0,NA(),IVC!C21) -> 139559 | H21: =IF(BR!C21=0,NA(),BR!C21) -> 45484 | I21: =E21/D21 -> 0.64523667 | U21: 17/18 | V21: =IFERROR(V8/V7-1,"") -> 0.033452915 | W21: =IFERROR(W8/W7-1,"") -> 0.040323904 | X21: =IFERROR(X8/X7-1,"") -> 0.049517928 | Y21: =IFERROR(Y8/Y7-1,"") -> 0.027851333
B22: Q4 | 19/20 | C22: =SUM(D22:H22) -> 860903 | D22: =IF(ECA!C22=0,NA(),ECA!C22) -> 345730 | E22: =IF(CAA!C22=0,NA(),CAA!C22) -> 202665 | F22: =IF(NCA!C22=0,NA(),NCA!C22) -> 118260 | G22: =IF(IVC!C22=0,NA(),IVC!C22) -> 135954 | H22: =IF(BR!C22=0,NA(),BR!C22) -> 58294 | I22: =E22/D22 -> 0.58619443 | U22: 18/19 | V22: =IFERROR(V9/V8-1,"") -> 0.036718907 | W22: =IFERROR(W9/W8-1,"") -> 0.040027625 | X22: =IFERROR(X9/X8-1,"") -> 0.054078063 | Y22: =IFERROR(Y9/Y8-1,"") -> 0.041431113 | AE22: =_xlfn.XLOOKUP(AF18,V6:Y6,V5:Y5) -> 3
B23: Q1 | 20/21 | C23: =SUM(D23:H23) -> 890571 | D23: =IF(ECA!C23=0,NA(),ECA!C23) -> 344151 | E23: =IF(CAA!C23=0,NA(),CAA!C23) -> 217546 | F23: =IF(NCA!C23=0,NA(),NCA!C23) -> 118043 | G23: =IF(IVC!C23=0,NA(),IVC!C23) -> 150241 | H23: =IF(BR!C23=0,NA(),BR!C23) -> 60590 | I23: =E23/D23 -> 0.63212369 | U23: 19/20 | V23: =IFERROR(V10/V9-1,"") -> 0.014831129 | W23: =IFERROR(W10/W9-1,"") -> 0.0020808685 | X23: =IFERROR(X10/X9-1,"") -> -0.079541516 | Y23: =IFERROR(Y10/Y9-1,"") -> -0.054751534 | AE23: Year
B24: Q2 | 20/21 | C24: =SUM(D24:H24) -> 900134 | D24: =IF(ECA!C24=0,NA(),ECA!C24) -> 357815 | E24: =IF(CAA!C24=0,NA(),CAA!C24) -> 213858 | F24: =IF(NCA!C24=0,NA(),NCA!C24) -> 117956 | G24: =IF(IVC!C24=0,NA(),IVC!C24) -> 150593 | H24: =IF(BR!C24=0,NA(),BR!C24) -> 59912 | I24: =E24/D24 -> 0.59767757 | U24: 20/21 | V24: =IFERROR(V11/V10-1,"") -> -0.0042732893 | W24: =IFERROR(W11/W10-1,"") -> 0.0092715826 | X24: =IFERROR(X11/X10-1,"") -> 0.065108214 | Y24: =IFERROR(Y11/Y10-1,"") -> 0.069106508 | AE24: 16/17 | AF24: {=OFFSET(U7,0,$AE$22,COUNT($V$7:$V$16),1)} -> 798014
B25: Q3 | 20/21 | C25: =SUM(D25:H25) -> 865508 | D25: =IF(ECA!C25=0,NA(),ECA!C25) -> 356854 | E25: =IF(CAA!C25=0,NA(),CAA!C25) -> 220865 | F25: =IF(NCA!C25=0,NA(),NCA!C25) -> 123719 | G25: =IF(IVC!C25=0,NA(),IVC!C25) -> 109471 | H25: =IF(BR!C25=0,NA(),BR!C25) -> 54599 | I25: =E25/D25 -> 0.61892258 | U25: 21/22 | V25: =IFERROR(V12/V11-1,"") -> 0.04342944 | W25: =IFERROR(W12/W11-1,"") -> 0.013624638 | X25: =IFERROR(X12/X11-1,"") -> 0.058617598 | Y25: =IFERROR(Y12/Y11-1,"") -> 0.032265425 | AE25: 17/18 | AF25: 837530 | AH25: =_xlfn.CONCAT(A1," ",AF18," across Years") -> All Reported Grind : ECA + CAA + NCA + IVC (Gepex) + BR Q3 across Years
B26: Q4 | 20/21 | C26: =SUM(D26:H26) -> 920397 | D26: =IF(ECA!C26=0,NA(),ECA!C26) -> 375811 | E26: =IF(CAA!C26=0,NA(),CAA!C26) -> 210970 | F26: =IF(NCA!C26=0,NA(),NCA!C26) -> 123399 | G26: =IF(IVC!C26=0,NA(),IVC!C26) -> 154121 | H26: =IF(BR!C26=0,NA(),BR!C26) -> 56096 | I26: =E26/D26 -> 0.5613726 | U26: 22/23 | V26: =IFERROR(V13/V12-1,"") -> 0.001378534 | W26: =IFERROR(W13/W12-1,"") -> 0.052265568 | X26: =IFERROR(X13/X12-1,"") -> -0.03499403 | Y26: =IFERROR(Y13/Y12-1,"") -> -0.02886346 | AE26: 18/19 | AF26: 882822
B27: Q1 | 21/22 | C27: =SUM(D27:H27) -> 929248 | D27: =IF(ECA!C27=0,NA(),ECA!C27) -> 365826 | E27: =IF(CAA!C27=0,NA(),CAA!C27) -> 231309 | F27: =IF(NCA!C27=0,NA(),NCA!C27) -> 116641 | G27: =IF(IVC!C27=0,NA(),IVC!C27) -> 158272 | H27: =IF(BR!C27=0,NA(),BR!C27) -> 57200 | I27: =E27/D27 -> 0.6322924 | U27: 23/24 | V27: =IFERROR(V14/V13-1,"") -> -0.033950581 | W27: =IFERROR(W14/W13-1,"") -> -0.025572736 | X27: =IFERROR(X14/X13-1,"") -> -0.025010773 | Y27: =IFERROR(Y14/Y13-1,"") -> -0.0095548684 | AE27: 19/20 | AF27: 812601
B28: Q2 | 21/22 | C28: =SUM(D28:H28) -> 912398 | D28: =IF(ECA!C28=0,NA(),ECA!C28) -> 373498 | E28: =IF(CAA!C28=0,NA(),CAA!C28) -> 213313 | F28: =IF(NCA!C28=0,NA(),NCA!C28) -> 114694 | G28: =IF(IVC!C28=0,NA(),IVC!C28) -> 155454 | H28: =IF(BR!C28=0,NA(),BR!C28) -> 55439 | I28: =E28/D28 -> 0.5711222 | U28: 24/25 | V28: =IFERROR(V15/V14-1,"") -> -0.0054786932 | W28: =IFERROR(W15/W14-1,"") -> -0.032461709 | X28: =IFERROR(X15/X14-1,"") -> -0.085824155 | Y28: =IFERROR(Y15/Y14-1,"") -> -0.13075816 | AE28: 20/21 | AF28: 865508
B29: Q3 | 21/22 | C29: =SUM(D29:H29) -> 916242 | D29: =IF(ECA!C29=0,NA(),ECA!C29) -> 364081 | E29: =IF(CAA!C29=0,NA(),CAA!C29) -> 228895 | F29: =IF(NCA!C29=0,NA(),NCA!C29) -> 115899 | G29: =IF(IVC!C29=0,NA(),IVC!C29) -> 156723 | H29: =IF(BR!C29=0,NA(),BR!C29) -> 50644 | I29: =E29/D29 -> 0.62869252 | U29: 25/26 | V29: =IFERROR(V16/V15-1,"") -> -0.077670098 | W29: =IFERROR(W16/W15-1,"") -> -0.028906364 | X29: =IFERROR(X16/X15-1,"") -> 0.086677858 | AE29: 21/22 | AF29: 916242
B30: Q4 | 21/22 | C30: =SUM(D30:H30) -> 950094 | D30: =IF(ECA!C30=0,NA(),ECA!C30) -> 369679 | E30: =IF(CAA!C30=0,NA(),CAA!C30) -> 231080 | F30: =IF(NCA!C30=0,NA(),NCA!C30) -> 119244 | G30: =IF(IVC!C30=0,NA(),IVC!C30) -> 171000 | H30: =IF(BR!C30=0,NA(),BR!C30) -> 59091 | I30: =E30/D30 -> 0.62508284 | AE30: 22/23 | AF30: 884179
B31: Q1 | 22/23 | C31: =SUM(D31:H31) -> 930529 | D31: =IF(ECA!C31=0,NA(),ECA!C31) -> 359577 | E31: =IF(CAA!C31=0,NA(),CAA!C31) -> 230806 | F31: =IF(NCA!C31=0,NA(),NCA!C31) -> 107130 | G31: =IF(IVC!C31=0,NA(),IVC!C31) -> 172357 | H31: =IF(BR!C31=0,NA(),BR!C31) -> 60659 | I31: =E31/D31 -> 0.64188199 | AE31: 23/24 | AF31: 862065
B32: Q2 | 22/23 | C32: =SUM(D32:H32) -> 960085 | D32: =IF(ECA!C32=0,NA(),ECA!C32) -> 375375 | E32: =IF(CAA!C32=0,NA(),CAA!C32) -> 222028 | F32: =IF(NCA!C32=0,NA(),NCA!C32) -> 109666 | G32: =IF(IVC!C32=0,NA(),IVC!C32) -> 189000 | H32: =IF(BR!C32=0,NA(),BR!C32) -> 64016 | I32: =E32/D32 -> 0.59148318 | U32: QoQ Change | AE32: 24/25 | AF32: 788079
B33: Q3 | 22/23 | C33: =SUM(D33:H33) -> 884179 | D33: =IF(ECA!C33=0,NA(),ECA!C33) -> 343283 | E33: =IF(CAA!C33=0,NA(),CAA!C33) -> 213977 | F33: =IF(NCA!C33=0,NA(),NCA!C33) -> 102493 | G33: =IF(IVC!C33=0,NA(),IVC!C33) -> 162000 | H33: =IF(BR!C33=0,NA(),BR!C33) -> 62426 | I33: =E33/D33 -> 0.62332536 | V33: Q1 | W33: Q2 | X33: Q3 | Y33: Q4 | AE33: 25/26 | AF33: 856388
B34: Q4 | 22/23 | C34: =SUM(D34:H34) -> 922671 | D34: =IF(ECA!C34=0,NA(),ECA!C34) -> 366298 | E34: =IF(CAA!C34=0,NA(),CAA!C34) -> 211468 | F34: =IF(NCA!C34=0,NA(),NCA!C34) -> 97881 | G34: =IF(IVC!C34=0,NA(),IVC!C34) -> 183000 | H34: =IF(BR!C34=0,NA(),BR!C34) -> 64024 | I34: =E34/D34 -> 0.57731137 | U34: 16/17 | W34: =IFERROR(W7/V7-1,"") -> 0 | X34: =IFERROR(X7/W7-1,"") -> -0.029875187 | Y34: =IFERROR(Y7/X7-1,"") -> 0.066195581
B35: Q1 | 23/24 | C35: =SUM(D35:H35) -> 898937 | D35: =IF(ECA!C35=0,NA(),ECA!C35) -> 350739 | E35: =IF(CAA!C35=0,NA(),CAA!C35) -> 211202 | F35: =IF(NCA!C35=0,NA(),NCA!C35) -> 103971 | G35: =IF(IVC!C35=0,NA(),IVC!C35) -> 170000 | H35: =IF(BR!C35=0,NA(),BR!C35) -> 63025 | I35: =E35/D35 -> 0.60216286 | U35: 17/18 | V35: =IFERROR(V8/Y7-1,"") -> -0.00086032728 | W35: =IFERROR(W8/V8-1,"") -> 0.0066485748 | X35: =IFERROR(X8/W8-1,"") -> -0.021301558 | Y35: =IFERROR(Y8/X8-1,"") -> 0.044184686
B36: Q2 | 23/24 | C36: =SUM(D36:H36) -> 935533 | D36: =IF(ECA!C36=0,NA(),ECA!C36) -> 367287 | E36: =IF(CAA!C36=0,NA(),CAA!C36) -> 225562 | F36: =IF(NCA!C36=0,NA(),NCA!C36) -> 113683 | G36: =IF(IVC!C36=0,NA(),IVC!C36) -> 169059 | H36: =IF(BR!C36=0,NA(),BR!C36) -> 59942 | I36: =E36/D36 -> 0.61413009 | U36: 18/19 | V36: =IFERROR(V9/Y8-1,"") -> 0.0077595433 | W36: =IFERROR(W9/V9-1,"") -> 0.009861322 | X36: =IFERROR(X9/W9-1,"") -> -0.0080796573 | Y36: =IFERROR(Y9/X9-1,"") -> 0.031656438
B37: Q3 | 23/24 | C37: =SUM(D37:H37) -> 862065 | D37: =IF(ECA!C37=0,NA(),ECA!C37) -> 357502 | E37: =IF(CAA!C37=0,NA(),CAA!C37) -> 215528 | F37: =IF(NCA!C37=0,NA(),NCA!C37) -> 104781 | G37: =IF(IVC!C37=0,NA(),IVC!C37) -> 129819 | H37: =IF(BR!C37=0,NA(),BR!C37) -> 54435 | I37: =E37/D37 -> 0.60287215 | U37: 19/20 | V37: =IFERROR(V10/Y9-1,"") -> -0.01798041 | W37: =IFERROR(W10/V10-1,"") -> -0.002826498 | X37: =IFERROR(X10/W10-1,"") -> -0.088874437 | Y37: =IFERROR(Y10/X10-1,"") -> 0.059441226
B38: Q4 | 23/24 | C38: =SUM(D38:H38) -> 913855 | D38: =IF(ECA!C38=0,NA(),ECA!C38) -> 354334 | E38: =IF(CAA!C38=0,NA(),CAA!C38) -> 221205 | F38: =IF(NCA!C38=0,NA(),NCA!C38) -> 109264 | G38: =IF(IVC!C38=0,NA(),IVC!C38) -> 173684 | H38: =IF(BR!C38=0,NA(),BR!C38) -> 55368 | I38: =E38/D38 -> 0.62428387 | U38: 20/21 | V38: =IFERROR(V11/Y10-1,"") -> 0.03446149 | W38: =IFERROR(W11/V11-1,"") -> 0.010738055 | X38: =IFERROR(X11/W11-1,"") -> -0.038467606 | Y38: =IFERROR(Y11/X11-1,"") -> 0.063418247
B39: Q1 | 24/25 | C39: =SUM(D39:H39) -> 894012 | D39: =IF(ECA!C39=0,NA(),ECA!C39) -> 331853 | E39: =IF(CAA!C39=0,NA(),CAA!C39) -> 214505 | F39: =IF(NCA!C39=0,NA(),NCA!C39) -> 102761 | G39: =IF(IVC!C39=0,NA(),IVC!C39) -> 182325 | H39: =IF(BR!C39=0,NA(),BR!C39) -> 62568 | I39: =E39/D39 -> 0.6463856 | U39: 21/22 | V39: =IFERROR(V12/Y11-1,"") -> 0.0096165024 | W39: =IFERROR(W12/V12-1,"") -> -0.018132942 | X39: =IFERROR(X12/W12-1,"") -> 0.0042130737 | Y39: =IFERROR(Y12/X12-1,"") -> 0.036946571
B40: Q2 | 24/25 | C40: =SUM(D40:H40) -> 905164 | D40: =IF(ECA!C40=0,NA(),ECA!C40) -> 353522 | E40: =IF(CAA!C40=0,NA(),CAA!C40) -> 217459 | F40: =IF(NCA!C40=0,NA(),NCA!C40) -> 110278 | G40: =IF(IVC!C40=0,NA(),IVC!C40) -> 169163 | H40: =IF(BR!C40=0,NA(),BR!C40) -> 54742 | I40: =E40/D40 -> 0.61512155 | U40: 22/23 | V40: =IFERROR(V13/Y12-1,"") -> -0.020592699 | W40: =IFERROR(W13/V13-1,"") -> 0.031762578 | X40: =IFERROR(X13/W13-1,"") -> -0.07906175 | Y40: =IFERROR(Y13/X13-1,"") -> 0.043534171
B41: Q3 | 24/25 | C41: =SUM(D41:H41) -> 788079 | D41: =IF(ECA!C41=0,NA(),ECA!C41) -> 331762 | E41: =IF(CAA!C41=0,NA(),CAA!C41) -> 182118 | F41: =IF(NCA!C41=0,NA(),NCA!C41) -> 101865 | G41: =IF(IVC!C41=0,NA(),IVC!C41) -> 124277 | H41: =IF(BR!C41=0,NA(),BR!C41) -> 48057 | I41: =E41/D41 -> 0.54894171 | U41: 23/24 | V41: =IFERROR(V14/Y13-1,"") -> -0.025723145 | W41: =IFERROR(W14/V14-1,"") -> 0.040710306 | X41: =IFERROR(X14/W14-1,"") -> -0.078530634 | Y41: =IFERROR(Y14/X14-1,"") -> 0.060076676
B42: Q4 | 24/25 | C42: =SUM(D42:H42) -> 794361 | D42: =IF(ECA!C42=0,NA(),ECA!C42) -> 337353 | E42: =IF(CAA!C42=0,NA(),CAA!C42) -> 183413 | F42: =IF(NCA!C42=0,NA(),NCA!C42) -> 112784 | G42: =IF(IVC!C42=0,NA(),IVC!C42) -> 112341 | H42: =IF(BR!C42=0,NA(),BR!C42) -> 48470 | I42: =E42/D42 -> 0.54368273 | U42: 24/25 | V42: =IFERROR(V15/Y14-1,"") -> -0.02171351 | W42: =IFERROR(W15/V15-1,"") -> 0.012474105 | X42: =IFERROR(X15/W15-1,"") -> -0.12935225 | Y42: =IFERROR(Y15/X15-1,"") -> 0.0079712821
...

Sheet Proportion
A1: Quarter | B1: ECA | C1: CAA | D1: NCA | E1: IVC | F1: BR
A2: Q1 | 16/17 | B2: =TOTAL!D7/TOTAL!$C7 -> 0.41301428 | C2: =TOTAL!E7/TOTAL!$C7 -> 0.21572134 | D2: =TOTAL!F7/TOTAL!$C7 -> 0.14606565 | E2: =TOTAL!G7/TOTAL!$C7 -> 0.15439059 | F2: =TOTAL!H7/TOTAL!$C7 -> 0.070808144
A3: Q2 | 16/17 | B3: =TOTAL!D8/TOTAL!$C8 -> 0.41301428 | C3: =TOTAL!E8/TOTAL!$C8 -> 0.21572134 | D3: =TOTAL!F8/TOTAL!$C8 -> 0.14606565 | E3: =TOTAL!G8/TOTAL!$C8 -> 0.15439059 | F3: =TOTAL!H8/TOTAL!$C8 -> 0.070808144
A4: Q3 | 16/17 | B4: =TOTAL!D9/TOTAL!$C9 -> 0.41599521 | C4: =TOTAL!E9/TOTAL!$C9 -> 0.20159797 | D4: =TOTAL!F9/TOTAL!$C9 -> 0.15428927 | E4: =TOTAL!G9/TOTAL!$C9 -> 0.15914508 | F4: =TOTAL!H9/TOTAL!$C9 -> 0.068972474
A5: Q4 | 16/17 | B5: =TOTAL!D10/TOTAL!$C10 -> 0.41552397 | C5: =TOTAL!E10/TOTAL!$C10 -> 0.22261203 | D5: =TOTAL!F10/TOTAL!$C10 -> 0.14729344 | E5: =TOTAL!G10/TOTAL!$C10 -> 0.15043974 | F5: =TOTAL!H10/TOTAL!$C10 -> 0.064130817
A6: Q1 | 17/18 | B6: =TOTAL!D11/TOTAL!$C11 -> 0.41557827 | C6: =TOTAL!E11/TOTAL!$C11 -> 0.23111914 | D6: =TOTAL!F11/TOTAL!$C11 -> 0.13654752 | E6: =TOTAL!G11/TOTAL!$C11 -> 0.14586399 | F6: =TOTAL!H11/TOTAL!$C11 -> 0.070891076
A7: Q2 | 17/18 | B7: =TOTAL!D12/TOTAL!$C12 -> 0.41884689 | C7: =TOTAL!E12/TOTAL!$C12 -> 0.22231025 | D7: =TOTAL!F12/TOTAL!$C12 -> 0.13879842 | E7: =TOTAL!G12/TOTAL!$C12 -> 0.15191193 | F7: =TOTAL!H12/TOTAL!$C12 -> 0.0681325
A8: Q3 | 17/18 | B8: =TOTAL!D13/TOTAL!$C13 -> 0.42518955 | C8: =TOTAL!E13/TOTAL!$C13 -> 0.22135804 | D8: =TOTAL!F13/TOTAL!$C13 -> 0.14244385 | E8: =TOTAL!G13/TOTAL!$C13 -> 0.14924839 | F8: =TOTAL!H13/TOTAL!$C13 -> 0.061760176
A9: Q4 | 17/18 | B9: =TOTAL!D14/TOTAL!$C14 -> 0.41521675 | C9: =TOTAL!E14/TOTAL!$C14 -> 0.22459681 | D9: =TOTAL!F14/TOTAL!$C14 -> 0.1469282 | E9: =TOTAL!G14/TOTAL!$C14 -> 0.14447318 | F9: =TOTAL!H14/TOTAL!$C14 -> 0.068785047
A10: Q1 | 18/19 | B10: =TOTAL!D15/TOTAL!$C15 -> 0.40745948 | C10: =TOTAL!E15/TOTAL!$C15 -> 0.23703028 | D10: =TOTAL!F15/TOTAL!$C15 -> 0.13300701 | E10: =TOTAL!G15/TOTAL!$C15 -> 0.15375765 | F10: =TOTAL!H15/TOTAL!$C15 -> 0.068745589
A11: Q2 | 18/19 | B11: =TOTAL!D16/TOTAL!$C16 -> 0.41612763 | C11: =TOTAL!E16/TOTAL!$C16 -> 0.2341404 | D11: =TOTAL!F16/TOTAL!$C16 -> 0.13685306 | E11: =TOTAL!G16/TOTAL!$C16 -> 0.14943602 | F11: =TOTAL!H16/TOTAL!$C16 -> 0.063442894
A12: Q3 | 18/19 | B12: =TOTAL!D17/TOTAL!$C17 -> 0.39066765 | C12: =TOTAL!E17/TOTAL!$C17 -> 0.24418739 | D12: =TOTAL!F17/TOTAL!$C17 -> 0.1405153 | E12: =TOTAL!G17/TOTAL!$C17 -> 0.15744963 | F12: =TOTAL!H17/TOTAL!$C17 -> 0.06718002
A13: Q4 | 18/19 | B13: =TOTAL!D18/TOTAL!$C18 -> 0.39849841 | C13: =TOTAL!E18/TOTAL!$C18 -> 0.24743486 | D13: =TOTAL!F18/TOTAL!$C18 -> 0.13527909 | E13: =TOTAL!G18/TOTAL!$C18 -> 0.1542356 | F13: =TOTAL!H18/TOTAL!$C18 -> 0.064552043
... A40: Q3 | 25/26 | B40: =TOTAL!D45/TOTAL!$C45 -> 0.369419 | C40: =TOTAL!E45/TOTAL!$C45 -> 0.26231801 | D40: =TOTAL!F45/TOTAL!$C45 -> 0.12804827 | E40: =TOTAL!G45/TOTAL!$C45 -> 0.17926454 | F40: =TOTAL!H45/TOTAL!$C45 -> 0.060950177

Sheet ECA
A1: ECA Grinds
X3: =COUNT(Q16:T16) -> 4 | Y3: =OFFSET(P6,0,$X$3,1,1) -> Q4
Q5: 1 | R5: 2 | S5: 3 | T5: 4
B6: Quarter | C6: Grind | Q6: Q1 | R6: Q2 | S6: Q3 | T6: Q4 | U6: Q1-Q4 | V6: % | X6: Crop Year | Y6: =_xlfn.CONCAT("YTD (Q1 to ",Y3,")") -> YTD (Q1 to Q4) | Z6: % | AD6: Q1 | AE6: Q2 | AF6: Q3 | AG6: Q4
B7: Q1 | 16/17 | C7: =C8 -> 339741 | P7: 16/17 | Q7: =C7 -> 339741 | R7: =C8 -> 339741 | S7: =C9 -> 331970 | T7: =C10 -> 353544 | U7: =SUM(Q7:T7) -> 1364996 | X7: =P7 -> 16/17 | Y7: =SUM(OFFSET(Q7,0,0,1,$X$3)) -> 1364996 | AC7: =P7 -> 16/17 | AD7: =Q7 -> 339741 | AE7: =AD7+R7 -> 679482 | AF7: =AE7+S7 -> 1011452 | AG7: =AF7+T7 -> 1364996
B8: Q2 | 16/17 | C8: 339741 | P8: 17/18 | Q8: =C11 -> 353286 | R8: =C12 -> 358432 | S8: =C13 -> 356109 | T8: =C14 -> 363122 | U8: =SUM(Q8:T8) -> 1430949 | V8: =U8/U7-1 -> 0.048317358 | X8: =P8 -> 17/18 | Y8: =SUM(OFFSET(Q8,0,0,1,$X$3)) -> 1430949 | Z8: =Y8/Y7-1 -> 0.048317358 | AC8: =P8 -> 17/18 | AD8: =Q8 -> 353286 | AE8: =AD8+R8 -> 711718 | AF8: =AE8+S8 -> 1067827 | AG8: =AF8+T8 -> 1430949
B9: Q3 | 16/17 | C9: 331970 | P9: 18/19 | Q9: =C15 -> 359103 | R9: =C16 -> 370359 | S9: =C17 -> 344890 | T9: =C18 -> 362940 | U9: =SUM(Q9:T9) -> 1437292 | V9: =U9/U8-1 -> 0.0044327226 | X9: =P9 -> 18/19 | Y9: =SUM(OFFSET(Q9,0,0,1,$X$3)) -> 1437292 | Z9: =Y9/Y8-1 -> 0.0044327226 | AC9: =P9 -> 18/19 | AD9: =Q9 -> 359103 | AE9: =AD9+R9 -> 729462 | AF9: =AE9+S9 -> 1074352 | AG9: =AF9+T9 -> 1437292
B10: Q4 | 16/17 | C10: 353544 | P10: 19/20 | Q10: =C19 -> 355201 | R10: =C20 -> 368934 | S10: =C21 -> 314108 | T10: =C22 -> 345730 | U10: =SUM(Q10:T10) -> 1383973 | V10: =U10/U9-1 -> -0.037096846 | X10: =P10 -> 19/20 | Y10: =SUM(OFFSET(Q10,0,0,1,$X$3)) -> 1383973 | Z10: =Y10/Y9-1 -> -0.037096846 | AC10: =P10 -> 19/20 | AD10: =Q10 -> 355201 | AE10: =AD10+R10 -> 724135 | AF10: =AE10+S10 -> 1038243 | AG10: =AF10+T10 -> 1383973
B11: Q1 | 17/18 | C11: 353286 | P11: 20/21 | Q11: =C23 -> 344151 | R11: =C24 -> 357815 | S11: =C25 -> 356854 | T11: =C26 -> 375811 | U11: =SUM(Q11:T11) -> 1434631 | V11: =U11/U10-1 -> 0.036603315 | X11: =P11 -> 20/21 | Y11: =SUM(OFFSET(Q11,0,0,1,$X$3)) -> 1434631 | Z11: =Y11/Y10-1 -> 0.036603315 | AC11: =P11 -> 20/21 | AD11: =Q11 -> 344151 | AE11: =AD11+R11 -> 701966 | AF11: =AE11+S11 -> 1058820 | AG11: =AF11+T11 -> 1434631
B12: Q2 | 17/18 | C12: 358432 | P12: 21/22 | Q12: =C27 -> 365826 | R12: =C28 -> 373498 | S12: =C29 -> 364081 | T12: =C30 -> 369679 | U12: =SUM(Q12:T12) -> 1473084 | V12: =U12/U11-1 -> 0.026803408 | X12: =P12 -> 21/22 | Y12: =SUM(OFFSET(Q12,0,0,1,$X$3)) -> 1473084 | Z12: =Y12/Y11-1 -> 0.026803408 | AC12: =P12 -> 21/22 | AD12: =Q12 -> 365826 | AE12: =AD12+R12 -> 739324 | AF12: =AE12+S12 -> 1103405 | AG12: =AF12+T12 -> 1473084
B13: Q3 | 17/18 | C13: 356109 | P13: 22/23 | Q13: =IF(C31=0,"",C31) -> 359577 | R13: =IF(C32=0,"",C32) -> 375375 | S13: =IF(C33=0,"",C33) -> 343283 | T13: =IF(C34=0,NA(),C34) -> 366298 | U13: =SUM(Q13:T13) -> 1444533 | V13: =U13/U12-1 -> -0.019381787 | X13: =P13 -> 22/23 | Y13: =SUM(OFFSET(Q13,0,0,1,$X$3)) -> 1444533 | Z13: =Y13/Y12-1 -> -0.019381787 | AC13: =P13 -> 22/23 | AD13: =Q13 -> 359577 | AE13: =AD13+R13 -> 734952 | AF13: =AE13+S13 -> 1078235 | AG13: =AF13+T13 -> 1444533
B14: Q4 | 17/18 | C14: 363122 | P14: 23/24 | Q14: =C35 -> 350739 | R14: =C36 -> 367287 | S14: =C37 -> 357502 | T14: =C38 -> 354334 | U14: =SUM(Q14:T14) -> 1429862 | V14: =U14/U13-1 -> -0.010156223 | X14: =P14 -> 23/24 | Y14: =SUM(OFFSET(Q14,0,0,1,$X$3)) -> 1429862 | Z14: =Y14/Y13-1 -> -0.010156223 | AC14: =P14 -> 23/24 | AD14: =Q14 -> 350739 | AE14: =AD14+R14 -> 718026 | AF14: =AE14+S14 -> 1075528 | AG14: =AF14+T14 -> 1429862
B15: Q1 | 18/19 | C15: 359103 | P15: 24/25 | Q15: =C39 -> 331853 | R15: =C40 -> 353522 | S15: =C41 -> 331762 | T15: =C42 -> 337353 | U15: =SUM(Q15:T15) -> 1354490 | V15: =U15/U14-1 -> -0.052712779 | X15: 24/25 | Y15: =SUM(OFFSET(Q15,0,0,1,$X$3)) -> 1354490 | Z15: =Y15/Y14-1 -> -0.052712779 | AC15: =P15 -> 24/25 | AD15: =Q15 -> 331853
B16: Q2 | 18/19 | C16: 370359 | P16: 25/26 | Q16: =C43 -> 304470 | R16: =C44 -> 325895 | S16: =C45 -> 316366 | T16: =C46 -> 348215 | U16: =SUM(Q16:T16) -> 1294946 | V16: =U16/U15-1 -> -0.043960457 | X16: 25/26 | Y16: =SUM(OFFSET(Q16,0,0,1,$X$3)) -> 1294946 | Z16: =Y16/Y15-1 -> -0.043960457
B17: Q3 | 18/19 | C17: 344890 | P17: 26/27 | X17: 26/27
B18: Q4 | 18/19 | C18: 362940
B19: Q1 | 19/20 | C19: 355201 | P19: YoY Change | X19: Choose Quarter | Z19: Q4
B20: Q2 | 19/20 | C20: 368934 | Q20: Q1 | R20: Q2 | S20: Q3 | T20: Q4
B21: Q3 | 19/20 | C21: 314108 | P21: =P7 -> 16/17
B22: Q4 | 19/20 | C22: 345730 | P22: =P8 -> 17/18 | Q22: =IFERROR(Q8/Q7-1,"") -> 0.039868606 | R22: =IFERROR(R8/R7-1,"") -> 0.055015438 | S22: =IFERROR(S8/S7-1,"") -> 0.072714402 | T22: =IFERROR(T8/T7-1,"") -> 0.027091395
B23: Q1 | 20/21 | C23: 344151 | P23: =P9 -> 18/19 | Q23: =IFERROR(Q9/Q8-1,"") -> 0.016465413 | R23: =IFERROR(R9/R8-1,"") -> 0.033275489 | S23: =IFERROR(S9/S8-1,"") -> -0.031504399 | T23: =IFERROR(T9/T8-1,"") -> -0.00050120896 | Y23: =_xlfn.XLOOKUP(Z19,Q6:T6,Q5:T5) -> 4
B24: Q2 | 20/21 | C24: 357815 | P24: =P10 -> 19/20 | Q24: =IFERROR(Q10/Q9-1,"") -> -0.010865963 | R24: =IFERROR(R10/R9-1,"") -> -0.0038476181 | S24: =IFERROR(S10/S9-1,"") -> -0.089251645 | T24: =IFERROR(T10/T9-1,"") -> -0.047418306 | Y24: Year
B25: Q3 | 20/21 | C25: 356854 | P25: =P11 -> 20/21 | Q25: =IFERROR(Q11/Q10-1,"") -> -0.031109147 | R25: =IFERROR(R11/R10-1,"") -> -0.030138182 | S25: =IFERROR(S11/S10-1,"") -> 0.13608695 | T25: =IFERROR(T11/T10-1,"") -> 0.087007202 | Y25: =P21 -> 16/17 | Z25: {=OFFSET(P7,0,$Y$23,COUNT($Q$7:$Q$16),1)} -> 353544 | AB25: =_xlfn.CONCAT(A1," ",Z19," across Years") -> ECA Grinds Q4 across Years
B26: Q4 | 20/21 | C26: 375811 | P26: =P12 -> 21/22 | Q26: =IFERROR(Q12/Q11-1,"") -> 0.062981075 | R26: =IFERROR(R12/R11-1,"") -> 0.043829912 | S26: =IFERROR(S12/S11-1,"") -> 0.02025198 | T26: =IFERROR(T12/T11-1,"") -> -0.016316712 | Y26: =P22 -> 17/18 | Z26: 363122
B27: Q1 | 21/22 | C27: 365826 | P27: =P13 -> 22/23 | Q27: =IFERROR(Q13/Q12-1,"") -> -0.017081891 | R27: =IFERROR(R13/R12-1,"") -> 0.005025462 | S27: =IFERROR(S13/S12-1,"") -> -0.057124651 | T27: =IFERROR(T13/T12-1,"") -> -0.0091457724 | Y27: =P23 -> 18/19 | Z27: 362940
B28: Q2 | 21/22 | C28: 373498 | P28: =P14 -> 23/24 | Q28: =IFERROR(Q14/Q13-1,"") -> -0.02457888 | R28: =IFERROR(R14/R13-1,"") -> -0.021546454 | S28: =IFERROR(S14/S13-1,"") -> 0.041420635 | T28: =IFERROR(T14/T13-1,"") -> -0.032661931 | Y28: =P24 -> 19/20 | Z28: 345730
B29: Q3 | 21/22 | C29: 364081 | P29: 24/25 | Q29: =IFERROR(Q15/Q14-1,"") -> -0.053846307 | R29: =IFERROR(R15/R14-1,"") -> -0.037477504 | S29: =IFERROR(S15/S14-1,"") -> -0.071999597 | T29: =IFERROR(T15/T14-1,"") -> -0.04792371 | Y29: =P25 -> 20/21 | Z29: 375811
B30: Q4 | 21/22 | C30: 369679 | P30: 25/26 | Q30: =IFERROR(Q16/Q15-1,"") -> -0.082515451 | R30: =IFERROR(R16/R15-1,"") -> -0.078147895 | S30: =IFERROR(S16/S15-1,"") -> -0.046406761 | T30: =IFERROR(T16/T15-1,"") -> 0.032197728 | Y30: =P26 -> 21/22 | Z30: 369679
B31: Q1 | 22/23 | C31: 359577 | Y31: =P27 -> 22/23 | Z31: 366298
B32: Q2 | 22/23 | C32: 375375 | Y32: =P28 -> 23/24 | Z32: 354334
B33: Q3 | 22/23 | C33: 343283 | P33: QoQ Change | Y33: =P29 -> 24/25 | Z33: 337353
B34: Q4 | 22/23 | C34: 366298 | Q34: Q1 | R34: Q2 | S34: Q3 | T34: Q4 | Y34: 25/26 | Z34: 348215
B35: Q1 | 23/24 | C35: 350739 | P35: =P21 -> 16/17 | R35: =IFERROR(R7/Q7-1,"") -> 0 | S35: =IFERROR(S7/R7-1,"") -> -0.022873306 | T35: =IFERROR(T7/S7-1,"") -> 0.0649878
B36: Q2 | 23/24 | C36: 367287 | P36: =P22 -> 17/18 | Q36: =IFERROR(Q8/T7-1,"") -> -0.00072975358 | R36: =IFERROR(R8/Q8-1,"") -> 0.014566102 | S36: =IFERROR(S8/R8-1,"") -> -0.0064810062 | T36: =IFERROR(T8/S8-1,"") -> 0.019693408
B37: Q3 | 23/24 | C37: 357502 | P37: =P23 -> 18/19 | Q37: =IFERROR(Q9/T8-1,"") -> -0.011067906 | R37: =IFERROR(R9/Q9-1,"") -> 0.031344767 | S37: =IFERROR(S9/R9-1,"") -> -0.068768411 | T37: =IFERROR(T9/S9-1,"") -> 0.052335527
B38: Q4 | 23/24 | C38: 354334 | P38: =P24 -> 19/20 | Q38: =IFERROR(Q10/T9-1,"") -> -0.021323084 | R38: =IFERROR(R10/Q10-1,"") -> 0.038662616 | S38: =IFERROR(S10/R10-1,"") -> -0.14860653 | T38: =IFERROR(T10/S10-1,"") -> 0.10067238
B39: Q1 | 24/25 | C39: 331853 | P39: =P25 -> 20/21 | Q39: =IFERROR(Q11/T10-1,"") -> -0.0045671478 | R39: =IFERROR(R11/Q11-1,"") -> 0.039703502 | S39: =IFERROR(S11/R11-1,"") -> -0.0026857454 | T39: =IFERROR(T11/S11-1,"") -> 0.053122566
B40: Q2 | 24/25 | C40: 353522 | P40: =P26 -> 21/22 | Q40: =IFERROR(Q12/T11-1,"") -> -0.026569206 | R40: =IFERROR(R12/Q12-1,"") -> 0.020971719 | S40: =IFERROR(S12/R12-1,"") -> -0.025212986 | T40: =IFERROR(T12/S12-1,"") -> 0.015375699
B41: Q3 | 24/25 | C41: 331762 | P41: =P27 -> 22/23 | Q41: =IFERROR(Q13/T12-1,"") -> -0.02732641 | R41: =IFERROR(R13/Q13-1,"") -> 0.043934957 | S41: =IFERROR(S13/R13-1,"") -> -0.085493173 | T41: =IFERROR(T13/S13-1,"") -> 0.067043809
B42: Q4 | 24/25 | C42: 337353 | P42: =P28 -> 23/24 | Q42: =IFERROR(Q14/T13-1,"") -> -0.042476344 | R42: =IFERROR(R14/Q14-1,"") -> 0.047180382 | S42: =IFERROR(S14/R14-1,"") -> -0.026641291 | T42: =IFERROR(T14/S14-1,"") -> -0.0088614889
...

Sheet ECA (Larger History)
A1: ECA Grinds
X3: =COUNT(Q16:T16) -> 1 | Y3: =OFFSET(P6,0,$X$3,1,1) -> Q1
Q5: 1 | R5: 2 | S5: 3 | T5: 4
B6: Quarter | C6: Grind | Q6: Q1 | R6: Q2 | S6: Q3 | T6: Q4 | U6: Q1-Q4 | V6: % | X6: Crop Year | Y6: =_xlfn.CONCAT("YTD (Q1 to ",Y3,")") -> YTD (Q1 to Q1) | Z6: % | AD6: Q1 | AE6: Q2 | AF6: Q3 | AG6: Q4
B7: Q1 | 16/17 | C7: =C8 -> 339741 | P7: 16/17 | Q7: =C7 -> 339741 | R7: =C8 -> 339741 | S7: =C9 -> 331970 | T7: =C10 -> 353544 | U7: =SUM(Q7:T7) -> 1364996 | X7: =P7 -> 16/17 | Y7: =SUM(OFFSET(Q7,0,0,1,$X$3)) -> 339741 | AC7: =P7 -> 16/17 | AD7: =Q7 -> 339741 | AE7: =AD7+R7 -> 679482 | AF7: =AE7+S7 -> 1011452 | AG7: =AF7+T7 -> 1364996
B8: Q2 | 16/17 | C8: 339741 | P8: 17/18 | Q8: =C11 -> 353286 | R8: =C12 -> 358432 | S8: =C13 -> 356109 | T8: =C14 -> 363122 | U8: =SUM(Q8:T8) -> 1430949 | V8: =U8/U7-1 -> 0.048317358 | X8: =P8 -> 17/18 | Y8: =SUM(OFFSET(Q8,0,0,1,$X$3)) -> 353286 | Z8: =Y8/Y7-1 -> 0.039868606 | AC8: =P8 -> 17/18 | AD8: =Q8 -> 353286 | AE8: =AD8+R8 -> 711718 | AF8: =AE8+S8 -> 1067827 | AG8: =AF8+T8 -> 1430949
B9: Q3 | 16/17 | C9: 331970 | P9: 18/19 | Q9: =C15 -> 359103 | R9: =C16 -> 370359 | S9: =C17 -> 344890 | T9: =C18 -> 362940 | U9: =SUM(Q9:T9) -> 1437292 | V9: =U9/U8-1 -> 0.0044327226 | X9: =P9 -> 18/19 | Y9: =SUM(OFFSET(Q9,0,0,1,$X$3)) -> 359103 | Z9: =Y9/Y8-1 -> 0.016465413 | AC9: =P9 -> 18/19 | AD9: =Q9 -> 359103 | AE9: =AD9+R9 -> 729462 | AF9: =AE9+S9 -> 1074352 | AG9: =AF9+T9 -> 1437292
B10: Q4 | 16/17 | C10: 353544 | P10: 19/20 | Q10: =C19 -> 355201 | R10: =C20 -> 368934 | S10: =C21 -> 314108 | T10: =C22 -> 345730 | U10: =SUM(Q10:T10) -> 1383973 | V10: =U10/U9-1 -> -0.037096846 | X10: =P10 -> 19/20 | Y10: =SUM(OFFSET(Q10,0,0,1,$X$3)) -> 355201 | Z10: =Y10/Y9-1 -> -0.010865963 | AC10: =P10 -> 19/20 | AD10: =Q10 -> 355201 | AE10: =AD10+R10 -> 724135 | AF10: =AE10+S10 -> 1038243 | AG10: =AF10+T10 -> 1383973
B11: Q1 | 17/18 | C11: 353286 | P11: 20/21 | Q11: =C23 -> 344151 | R11: =C24 -> 357815 | S11: =C25 -> 356854 | T11: =C26 -> 375811 | U11: =SUM(Q11:T11) -> 1434631 | V11: =U11/U10-1 -> 0.036603315 | X11: =P11 -> 20/21 | Y11: =SUM(OFFSET(Q11,0,0,1,$X$3)) -> 344151 | Z11: =Y11/Y10-1 -> -0.031109147 | AC11: =P11 -> 20/21 | AD11: =Q11 -> 344151 | AE11: =AD11+R11 -> 701966 | AF11: =AE11+S11 -> 1058820 | AG11: =AF11+T11 -> 1434631
B12: Q2 | 17/18 | C12: 358432 | P12: 21/22 | Q12: =C27 -> 365826 | R12: =C28 -> 373498 | S12: =C29 -> 364081 | T12: =C30 -> 369679 | U12: =SUM(Q12:T12) -> 1473084 | V12: =U12/U11-1 -> 0.026803408 | X12: =P12 -> 21/22 | Y12: =SUM(OFFSET(Q12,0,0,1,$X$3)) -> 365826 | Z12: =Y12/Y11-1 -> 0.062981075 | AC12: =P12 -> 21/22 | AD12: =Q12 -> 365826 | AE12: =AD12+R12 -> 739324 | AF12: =AE12+S12 -> 1103405 | AG12: =AF12+T12 -> 1473084
B13: Q3 | 17/18 | C13: 356109 | P13: 22/23 | Q13: =IF(C31=0,"",C31) -> 359577 | R13: =IF(C32=0,"",C32) -> 375375 | S13: =IF(C33=0,"",C33) -> 343283 | T13: =IF(C34=0,NA(),C34) -> 366298 | U13: =SUM(Q13:T13) -> 1444533 | V13: =U13/U12-1 -> -0.019381787 | X13: =P13 -> 22/23 | Y13: =SUM(OFFSET(Q13,0,0,1,$X$3)) -> 359577 | Z13: =Y13/Y12-1 -> -0.017081891 | AC13: =P13 -> 22/23 | AD13: =Q13 -> 359577 | AE13: =AD13+R13 -> 734952 | AF13: =AE13+S13 -> 1078235 | AG13: =AF13+T13 -> 1444533
B14: Q4 | 17/18 | C14: 363122 | P14: 23/24 | Q14: =C35 -> 350739 | R14: =C36 -> 367287 | S14: =C37 -> 357502 | T14: =C38 -> 354334 | U14: =SUM(Q14:T14) -> 1429862 | V14: =U14/U13-1 -> -0.010156223 | X14: =P14 -> 23/24 | Y14: =SUM(OFFSET(Q14,0,0,1,$X$3)) -> 350739 | Z14: =Y14/Y13-1 -> -0.02457888 | AC14: =P14 -> 23/24 | AD14: =Q14 -> 350739 | AE14: =AD14+R14 -> 718026 | AF14: =AE14+S14 -> 1075528 | AG14: =AF14+T14 -> 1429862
B15: Q1 | 18/19 | C15: 359103 | P15: 24/25 | Q15: =C39 -> 331853 | R15: =C40 -> 353522 | S15: =C41 -> 331762 | T15: =C42 -> 337353 | U15: =SUM(Q15:T15) -> 1354490 | V15: =U15/U14-1 -> -0.052712779 | X15: 24/25 | Y15: =SUM(OFFSET(Q15,0,0,1,$X$3)) -> 331853 | Z15: =Y15/Y14-1 -> -0.053846307 | AC15: =P15 -> 24/25 | AD15: =Q15 -> 331853
B16: Q2 | 18/19 | C16: 370359 | P16: 25/26 | Q16: =C43 -> 304470 | X16: 25/26 | Y16: =SUM(OFFSET(Q16,0,0,1,$X$3)) -> 304470 | Z16: =Y16/Y15-1 -> -0.082515451
B17: Q3 | 18/19 | C17: 344890 | P17: 26/27 | X17: 26/27
B18: Q4 | 18/19 | C18: 362940
B19: Q1 | 19/20 | C19: 355201 | X19: Choose Quarter | Z19: Q1
B20: Q2 | 19/20 | C20: 368934
B21: Q3 | 19/20 | C21: 314108
B22: Q4 | 19/20 | C22: 345730
B23: Q1 | 20/21 | C23: 344151 | Y23: =_xlfn.XLOOKUP(Z19,Q6:T6,Q5:T5) -> 1
B24: Q2 | 20/21 | C24: 357815 | Y24: Year
B25: Q3 | 20/21 | C25: 356854 | Y25: =P50 -> 16/17 | Z25: {=OFFSET(P7,0,$Y$23,COUNT($Q$7:$Q$16),1)} -> 339741 | AB25: =_xlfn.CONCAT(A1," ",Z19," across Years") -> ECA Grinds Q1 across Years
B26: Q4 | 20/21 | C26: 375811 | Y26: =P51 -> 17/18 | Z26: 353286
B27: Q1 | 21/22 | C27: 365826 | Y27: =P52 -> 18/19 | Z27: 359103
B28: Q2 | 21/22 | C28: 373498 | Y28: =P53 -> 19/20 | Z28: 355201
B29: Q3 | 21/22 | C29: 364081 | Y29: =P54 -> 20/21 | Z29: 344151
B30: Q4 | 21/22 | C30: 369679 | Y30: =P55 -> 21/22 | Z30: 365826
B31: Q1 | 22/23 | C31: 359577 | Y31: =P56 -> 22/23 | Z31: 359577
B32: Q2 | 22/23 | C32: 375375 | Y32: =P57 -> 23/24 | Z32: 350739
B33: Q3 | 22/23 | C33: 343283 | Y33: =P58 -> 24/25 | Z33: 331853
B34: Q4 | 22/23 | C34: 366298 | Y34: 25/26 | Z34: 304470
B35: Q1 | 23/24 | C35: 350739
B36: Q2 | 23/24 | C36: 367287
B37: Q3 | 23/24 | C37: 357502
B38: Q4 | 23/24 | C38: 354334
B39: Q1 | 24/25 | C39: 331853
B40: Q2 | 24/25 | C40: 353522
B41: Q3 | 24/25 | C41: 331762
B42: Q4 | 24/25 | C42: 337353
...

Sheet History Maker
F3: Quarter | G3: Crop Year | H3: Name | I3: Grind | J3: Rows | K3: Column | AB3: COC-GRN-ECA
F4: Q1 | G4: 0/1 | H4: Q1 | 0/1 | I4: 307473 | J4: 1 | K4: 1 | P4: Sum of Grind | Q4: Column Labels
F5: Q2 | G5: 0/1 | H5: Q2 | 0/1 | I5: 307764 | J5: 1 | K5: 2 | P5: Row Labels | Q5: 1 | R5: 2 | S5: 3 | T5: 4 | X5: =_xll.RDP.HistoricalPricing($AB$3,"CLOSE","SOURCE:RFV NBROWS:2500 INTERVAL:P3M",,"SORT:ASC CH:Fd RH:Timestamp",Z6) -> Not Signed In
F6: Q3 | G6: 0/1 | H6: Q3 | 0/1 | I6: 284048 | J6: 1 | K6: 3 | P6: 1 | Q6: 307473 | R6: 307764 | S6: 284048 | T6: 287709 | Z6: Timestamp | AA6: CLOSE
F7: Q4 | G7: 0/1 | H7: Q4 | 0/1 | I7: 287709 | J7: 1 | K7: 4 | P7: 2 | Q7: 286947 | R7: 264755 | S7: 257570 | T7: 271041 | Z7: 36250 | AA7: 261792
F8: Q1 | G8: 1/2 | H8: Q1 | 1/2 | I8: 286947 | J8: =J4+1 -> 2 | K8: =K4 -> 1 | P8: 3 | Q8: 282501 | R8: 276070 | S8: 270197 | T8: 279675 | Z8: 36341 | AA8: 262073
F9: Q2 | G9: 1/2 | H9: Q2 | 1/2 | I9: 264755 | J9: =J5+1 -> 2 | K9: =K5 -> 2 | P9: 4 | Q9: 302988 | R9: 292367 | S9: 272570 | T9: 287040 | Z9: 36433 | AA9: 259907
F10: Q3 | G10: 1/2 | H10: Q3 | 1/2 | I10: 257570 | J10: =J6+1 -> 2 | K10: =K6 -> 3 | P10: 5 | Q10: 301214 | R10: 295061 | S10: 295926 | T10: 311627 | Z10: 36525 | AA10: 285952
F11: Q4 | G11: 1/2 | H11: Q4 | 1/2 | I11: 271041 | J11: =J7+1 -> 2 | K11: =K7 -> 4 | P11: 6 | Q11: 317000 | R11: 324173 | S11: 312817 | T11: 324903 | Z11: 36616 | AA11: 292628
F12: Q1 | G12: 2/3 | H12: Q1 | 2/3 | I12: 282501 | J12: =J8+1 -> 3 | K12: =K8 -> 1 | P12: 7 | Q12: 338922 | R12: 338495 | S12: 323353 | T12: 351040 | Z12: 36707 | AA12: 275663
F13: Q2 | G13: 2/3 | H13: Q2 | 2/3 | I13: 276070 | J13: =J9+1 -> 3 | K13: =K9 -> 2 | P13: 8 | Q13: 348901 | R13: 354571 | S13: 328920 | T13: 348501 | Z13: 36799 | AA13: 297164
F14: Q3 | G14: 2/3 | H14: Q3 | 2/3 | I14: 270197 | J14: =J10+1 -> 3 | K14: =K10 -> 3 | P14: 9 | Q14: 349351 | R14: 315177 | S14: 291763 | T14: 344832 | Z14: 36891 | AA14: 307473 | AF14: Q1 | AG14: 0/1 | AH14: =_xlfn.CONCAT(AF14," | ",AG14) -> Q1 | 0/1 | AI14: =AA14 -> 307473
F15: Q4 | G15: 2/3 | H15: Q4 | 2/3 | I15: 279675 | J15: =J11+1 -> 3 | K15: =K11 -> 4 | P15: 10 | Q15: 351316 | R15: 341096 | S15: 328426 | T15: 330900 | Z15: 36981 | AA15: 307764 | AF15: Q2 | AG15: =AG14 -> 0/1 | AH15: =_xlfn.CONCAT(AF15," | ",AG15) -> Q2 | 0/1 | AI15: =AA15 -> 307764
F16: Q1 | G16: 3/4 | H16: Q1 | 3/4 | I16: 302988 | J16: =J12+1 -> 4 | K16: =K12 -> 1 | P16: 11 | Q16: 343243 | R16: 354603 | S16: 355763 | T16: 378042 | Z16: 37072 | AA16: 284048 | AF16: Q3 | AG16: =AG15 -> 0/1 | AH16: =_xlfn.CONCAT(AF16," | ",AG16) -> Q3 | 0/1 | AI16: =AA16 -> 284048
F17: Q2 | G17: 3/4 | H17: Q2 | 3/4 | I17: 292367 | J17: =J13+1 -> 4 | K17: =K13 -> 2 | P17: 12 | Q17: 349756 | R17: 353311 | S17: 292551 | T17: 316676 | Z17: 37164 | AA17: 287709 | AF17: Q4 | AG17: =AG16 -> 0/1 | AH17: =_xlfn.CONCAT(AF17," | ",AG17) -> Q4 | 0/1 | AI17: =AA17 -> 287709
F18: Q3 | G18: 3/4 | H18: Q3 | 3/4 | I18: 272570 | J18: =J14+1 -> 4 | K18: =K14 -> 3 | P18: 13 | Q18: 327982 | R18: 339377 | S18: 310188 | T18: 331514 | Z18: 37256 | AA18: 286947 | AF18: Q1 | AG18: 1/2 | AH18: =_xlfn.CONCAT(AF18," | ",AG18) -> Q1 | 1/2 | AI18: =AA18 -> 286947
F19: Q4 | G19: 3/4 | H19: Q4 | 3/4 | I19: 287040 | J19: =J15+1 -> 4 | K19: =K15 -> 4 | P19: 14 | Q19: 348963 | R19: 343210 | S19: 308236 | T19: 327316 | Z19: 37346 | AA19: 264755 | AF19: Q2 | AG19: =AG18 -> 1/2 | AH19: =_xlfn.CONCAT(AF19," | ",AG19) -> Q2 | 1/2 | AI19: =AA19 -> 264755
F20: Q1 | G20: 4/5 | H20: Q1 | 4/5 | I20: 301214 | J20: =J16+1 -> 5 | K20: =K16 -> 1 | P20: 15 | Q20: 321935 | R20: 337425 | S20: 310158 | T20: 333002 | Z20: 37437 | AA20: 257570 | AF20: Q3 | AG20: =AG19 -> 1/2 | AH20: =_xlfn.CONCAT(AF20," | ",AG20) -> Q3 | 1/2 | AI20: =AA20 -> 257570
F21: Q2 | G21: 4/5 | H21: Q2 | 4/5 | I21: 295061 | J21: =J17+1 -> 5 | K21: =K17 -> 2 | P21: 16 | Q21: 340986 | R21: 335806 | S21: 325698 | T21: 343238 | Z21: 37529 | AA21: 271041 | AF21: Q4 | AG21: =AG20 -> 1/2 | AH21: =_xlfn.CONCAT(AF21," | ",AG21) -> Q4 | 1/2 | AI21: =AA21 -> 271041
F22: Q3 | G22: 4/5 | H22: Q3 | 4/5 | I22: 295926 | J22: =J18+1 -> 5 | K22: =K18 -> 3 | Z22: 37621 | AA22: 282501 | AF22: Q1 | AG22: 2/3 | AH22: =_xlfn.CONCAT(AF22," | ",AG22) -> Q1 | 2/3 | AI22: =AA22 -> 282501
F23: Q4 | G23: 4/5 | H23: Q4 | 4/5 | I23: 311627 | J23: =J19+1 -> 5 | K23: =K19 -> 4 | Z23: 37711 | AA23: 276070 | AF23: Q2 | AG23: =AG22 -> 2/3 | AH23: =_xlfn.CONCAT(AF23," | ",AG23) -> Q2 | 2/3 | AI23: =AA23 -> 276070
F24: Q1 | G24: 5/6 | H24: Q1 | 5/6 | I24: 317000 | J24: =J20+1 -> 6 | K24: =K20 -> 1 | Z24: 37802 | AA24: 270197 | AF24: Q3 | AG24: =AG23 -> 2/3 | AH24: =_xlfn.CONCAT(AF24," | ",AG24) -> Q3 | 2/3 | AI24: =AA24 -> 270197
F25: Q2 | G25: 5/6 | H25: Q2 | 5/6 | I25: 324173 | J25: =J21+1 -> 6 | K25: =K21 -> 2 | Z25: 37894 | AA25: 279675 | AF25: Q4 | AG25: =AG24 -> 2/3 | AH25: =_xlfn.CONCAT(AF25," | ",AG25) -> Q4 | 2/3 | AI25: =AA25 -> 279675
F26: Q3 | G26: 5/6 | H26: Q3 | 5/6 | I26: 312817 | J26: =J22+1 -> 6 | K26: =K22 -> 3 | Q26: 1 | R26: 2 | S26: 3 | T26: 4 | Z26: 37986 | AA26: 302988 | AF26: Q1 | AG26: 3/4 | AH26: =_xlfn.CONCAT(AF26," | ",AG26) -> Q1 | 3/4 | AI26: =AA26 -> 302988
F27: Q4 | G27: 5/6 | H27: Q4 | 5/6 | I27: 324903 | J27: =J23+1 -> 6 | K27: =K23 -> 4 | O27: =_xlfn.XLOOKUP(P27,J:J,G:G) -> 0/1 | P27: 1 | Q27: 307473 | R27: 307764 | S27: 284048 | T27: 287709 | Z27: 38077 | AA27: 292367 | AF27: Q2 | AG27: =AG26 -> 3/4 | AH27: =_xlfn.CONCAT(AF27," | ",AG27) -> Q2 | 3/4 | AI27: =AA27 -> 292367
F28: Q1 | G28: 6/7 | H28: Q1 | 6/7 | I28: 338922 | J28: =J24+1 -> 7 | K28: =K24 -> 1 | O28: =_xlfn.XLOOKUP(P28,J:J,G:G) -> 1/2 | P28: 2 | Q28: 286947 | R28: 264755 | S28: 257570 | T28: 271041 | Z28: 38168 | AA28: 272570 | AF28: Q3 | AG28: =AG27 -> 3/4 | AH28: =_xlfn.CONCAT(AF28," | ",AG28) -> Q3 | 3/4 | AI28: =AA28 -> 272570
F29: Q2 | G29: 6/7 | H29: Q2 | 6/7 | I29: 338495 | J29: =J25+1 -> 7 | K29: =K25 -> 2 | O29: =_xlfn.XLOOKUP(P29,J:J,G:G) -> 2/3 | P29: 3 | Q29: 282501 | R29: 276070 | S29: 270197 | T29: 279675 | Z29: 38260 | AA29: 287040 | AF29: Q4 | AG29: =AG28 -> 3/4 | AH29: =_xlfn.CONCAT(AF29," | ",AG29) -> Q4 | 3/4 | AI29: =AA29 -> 287040
F30: Q3 | G30: 6/7 | H30: Q3 | 6/7 | I30: 323353 | J30: =J26+1 -> 7 | K30: =K26 -> 3 | O30: =_xlfn.XLOOKUP(P30,J:J,G:G) -> 3/4 | P30: 4 | Q30: 302988 | R30: 292367 | S30: 272570 | T30: 287040 | Z30: 38352 | AA30: 301214 | AF30: Q1 | AG30: 4/5 | AH30: =_xlfn.CONCAT(AF30," | ",AG30) -> Q1 | 4/5 | AI30: =AA30 -> 301214
F31: Q4 | G31: 6/7 | H31: Q4 | 6/7 | I31: 351040 | J31: =J27+1 -> 7 | K31: =K27 -> 4 | O31: =_xlfn.XLOOKUP(P31,J:J,G:G) -> 4/5 | P31: 5 | Q31: 301214 | R31: 295061 | S31: 295926 | T31: 311627 | Z31: 38442 | AA31: 295061 | AF31: Q2 | AG31: =AG30 -> 4/5 | AH31: =_xlfn.CONCAT(AF31," | ",AG31) -> Q2 | 4/5 | AI31: =AA31 -> 295061
F32: Q1 | G32: 7/8 | H32: Q1 | 7/8 | I32: 348901 | J32: =J28+1 -> 8 | K32: =K28 -> 1 | O32: =_xlfn.XLOOKUP(P32,J:J,G:G) -> 5/6 | P32: 6 | Q32: 317000 | R32: 324173 | S32: 312817 | T32: 324903 | Z32: 38533 | AA32: 295926 | AF32: Q3 | AG32: =AG31 -> 4/5 | AH32: =_xlfn.CONCAT(AF32," | ",AG32) -> Q3 | 4/5 | AI32: =AA32 -> 295926
F33: Q2 | G33: 7/8 | H33: Q2 | 7/8 | I33: 354571 | J33: =J29+1 -> 8 | K33: =K29 -> 2 | O33: =_xlfn.XLOOKUP(P33,J:J,G:G) -> 6/7 | P33: 7 | Q33: 338922 | R33: 338495 | S33: 323353 | T33: 351040 | Z33: 38625 | AA33: 311627 | AF33: Q4 | AG33: =AG32 -> 4/5 | AH33: =_xlfn.CONCAT(AF33," | ",AG33) -> Q4 | 4/5 | AI33: =AA33 -> 311627
F34: Q3 | G34: 7/8 | H34: Q3 | 7/8 | I34: 328920 | J34: =J30+1 -> 8 | K34: =K30 -> 3 | O34: =_xlfn.XLOOKUP(P34,J:J,G:G) -> 7/8 | P34: 8 | Q34: 348901 | R34: 354571 | S34: 328920 | T34: 348501 | Z34: 38717 | AA34: 317000 | AF34: Q1 | AG34: 5/6 | AH34: =_xlfn.CONCAT(AF34," | ",AG34) -> Q1 | 5/6 | AI34: =AA34 -> 317000
F35: Q4 | G35: 7/8 | H35: Q4 | 7/8 | I35: 348501 | J35: =J31+1 -> 8 | K35: =K31 -> 4 | O35: =_xlfn.XLOOKUP(P35,J:J,G:G) -> 8/9 | P35: 9 | Q35: 349351 | R35: 315177 | S35: 291763 | T35: 344832 | Z35: 38807 | AA35: 324173 | AF35: Q2 | AG35: =AG34 -> 5/6 | AH35: =_xlfn.CONCAT(AF35," | ",AG35) -> Q2 | 5/6 | AI35: =AA35 -> 324173
F36: Q1 | G36: 8/9 | H36: Q1 | 8/9 | I36: 349351 | J36: =J32+1 -> 9 | K36: =K32 -> 1 | O36: =_xlfn.XLOOKUP(P36,J:J,G:G) -> 9/10 | P36: 10 | Q36: 351316 | R36: 341096 | S36: 328426 | T36: 330900 | Z36: 38898 | AA36: 312817 | AF36: Q3 | AG36: =AG35 -> 5/6 | AH36: =_xlfn.CONCAT(AF36," | ",AG36) -> Q3 | 5/6 | AI36: =AA36 -> 312817
F37: Q2 | G37: 8/9 | H37: Q2 | 8/9 | I37: 315177 | J37: =J33+1 -> 9 | K37: =K33 -> 2 | O37: =_xlfn.XLOOKUP(P37,J:J,G:G) -> 10/11 | P37: 11 | Q37: 343243 | R37: 354603 | S37: 355763 | T37: 378042 | Z37: 38990 | AA37: 324903 | AF37: Q4 | AG37: =AG36 -> 5/6 | AH37: =_xlfn.CONCAT(AF37," | ",AG37) -> Q4 | 5/6 | AI37: =AA37 -> 324903
F38: Q3 | G38: 8/9 | H38: Q3 | 8/9 | I38: 291763 | J38: =J34+1 -> 9 | K38: =K34 -> 3 | O38: =_xlfn.XLOOKUP(P38,J:J,G:G) -> 11/12 | P38: 12 | Q38: 349756 | R38: 353311 | S38: 292551 | T38: 316676 | Z38: 39082 | AA38: 338922 | AF38: Q1 | AG38: 6/7 | AH38: =_xlfn.CONCAT(AF38," | ",AG38) -> Q1 | 6/7 | AI38: =AA38 -> 338922
F39: Q4 | G39: 8/9 | H39: Q4 | 8/9 | I39: 344832 | J39: =J35+1 -> 9 | K39: =K35 -> 4 | O39: =_xlfn.XLOOKUP(P39,J:J,G:G) -> 12/13 | P39: 13 | Q39: 327982 | R39: 339377 | S39: 310188 | T39: 331514 | Z39: 39172 | AA39: 338495 | AF39: Q2 | AG39: =AG38 -> 6/7 | AH39: =_xlfn.CONCAT(AF39," | ",AG39) -> Q2 | 6/7 | AI39: =AA39 -> 338495
F40: Q1 | G40: 9/10 | H40: Q1 | 9/10 | I40: 351316 | J40: =J36+1 -> 10 | K40: =K36 -> 1 | O40: =_xlfn.XLOOKUP(P40,J:J,G:G) -> 13/14 | P40: 14 | Q40: 348963 | R40: 343210 | S40: 308236 | T40: 327316 | Z40: 39263 | AA40: 323353 | AF40: Q3 | AG40: =AG39 -> 6/7 | AH40: =_xlfn.CONCAT(AF40," | ",AG40) -> Q3 | 6/7 | AI40: =AA40 -> 323353
F41: Q2 | G41: 9/10 | H41: Q2 | 9/10 | I41: 341096 | J41: =J37+1 -> 10 | K41: =K37 -> 2 | O41: =_xlfn.XLOOKUP(P41,J:J,G:G) -> 14/15 | P41: 15 | Q41: 321935 | R41: 337425 | S41: 310158 | T41: 333002 | Z41: 39355 | AA41: 351040 | AF41: Q4 | AG41: =AG40 -> 6/7 | AH41: =_xlfn.CONCAT(AF41," | ",AG41) -> Q4 | 6/7 | AI41: =AA41 -> 351040
F42: Q3 | G42: 9/10 | H42: Q3 | 9/10 | I42: 328426 | J42: =J38+1 -> 10 | K42: =K38 -> 3 | O42: =_xlfn.XLOOKUP(P42,J:J,G:G) -> 15/16 | P42: 16 | Q42: 340986 | R42: 335806 | S42: 325698 | T42: 343238 | Z42: 39447 | AA42: 348901 | AF42: Q1 | AG42: 7/8 | AH42: =_xlfn.CONCAT(AF42," | ",AG42) -> Q1 | 7/8 | AI42: =AA42 -> 348901
...

Sheet ECA Estimates
C6: Beq export | D6: Oct | E6: Nov | F6: Dec | G6: Jan | H6: Feb | I6: Mar | J6: Apr | K6: May | L6: Jun | M6: Jul | N6: Aug | O6: Sep
C7: 14/15 | D7: 23142.4 | E7: 18862.933 | F7: 16195.415 | G7: 22511.933 | H7: 19310.614 | I7: 16118.939 | J7: 17962.988 | K7: 20821.552 | L7: 20372.263 | M7: 19195.572 | N7: 21407.889 | O7: 26511.962
C8: 15/16 | D8: 22374.955 | E8: 22294.135 | F8: 18592.778 | G8: 23166.415 | H8: 17911.376 | I8: 20069.948 | J8: 21753.109 | K8: 19448.165 | L8: 19725.782 | M8: 15647.211 | N8: 23843.03 | O8: 22578.789
C9: 16/17 | D9: 24735.005 | E9: 22755.287 | F9: 20202.744 | G9: 26440.743 | H9: 21923.306 | I9: 23023.971 | J9: 18202.314 | K9: 20867.631 | L9: 22553.111 | M9: 18300.359 | N9: 24660.706 | O9: 23325.64
C10: 17/18 | D10: 28457.676 | E10: 27462.903 | F10: 18254.748 | G10: 25010.508 | H10: 20979.069 | I10: 22351.847 | J10: 24729.813 | K10: 24044.406 | L10: 23193.092 | M10: 21990.27 | N10: 23767.356 | O10: 22605.181
C11: 18/19 | D11: 27249.05 | E11: 26050.801 | F11: 18927.666 | G11: 27283.159 | H11: 25042.452 | I11: 24620.76 | J11: 23374.663 | K11: 23302.124 | L11: 22117.327 | M11: 24042.322 | N11: 27328.927 | O11: 25424.144
C12: 19/20 | D12: 26646.034 | E12: 23607.373 | F12: 22081.431 | G12: 24400.577 | H12: 23742.889 | I12: 24858.989 | J12: 19587.233 | K12: 17331.579 | L12: 19222.531 | M12: 21658.732 | N12: 22298.558 | O12: 25817.212
C13: 20/21 | D13: 26906.245 | E13: 23849.105 | F13: 21899.89 | G13: 24483.537 | H13: 23278.862 | I13: 26340.377 | J13: 28148.341 | K13: 25094.502 | L13: 27211.041 | M13: 25524.228 | N13: 26831.573 | O13: 27430.349
C14: 21/22 | D14: 30153.317 | E14: 30490.376 | F14: 25383.275 | G14: 28093.379 | H14: 26084.453 | I14: 23422.006 | J14: 19821.983 | K14: 24603.741 | L14: 26102.791 | M14: 23601.492 | N14: 29022.673 | O14: 31840.027
C15: 22/23 | D15: 30550.925 | E15: 33782.826 | F15: 26061.218 | G15: 32581.749 | H15: 27094.766 | I15: 26542.537 | J15: 24240.888 | K15: 26915.962 | L15: 26432.765 | M15: 26040.944 | N15: 29372.778 | O15: 27632.2
C16: 23/24 | D16: 28427.221 | E16: 28568.687 | F16: 22337.982 | G16: 31698.362 | H16: 27890.012 | I16: 26876.205 | J16: 34586.27 | K16: 31974.557 | L16: 28628.108 | M16: 31821.07 | N16: 28969.559 | O16: 31506.053
C17: 24/25 | D17: 31781.339 | E17: 25241.931 | F17: 18967.826 | G17: 31160.24 | H17: 30563.818 | I17: 28781.721 | J17: 23296.362 | K17: 28736.412 | L17: 24454.928 | M17: 23172.832 | N17: 24759.483 | O17: 26268.497
C18: 25/26 | D18: 31141.41
C21: Exports | D21: 1 | E21: 2 | F21: 3 | G21: 4 | K21: Exports | L21: 1 | M21: 2 | N21: 3 | O21: 4
B22: =C7 -> 14/15 | C22: 1 | D22: =SUM(D7:F7) -> 58200.748 | E22: =SUM(G7:I7) -> 57941.486 | F22: =SUM(J7:L7) -> 59156.803 | G22: =SUM(M7:O7) -> 67115.423 | J22: 14/15 | K22: 1
B23: =C8 -> 15/16 | C23: 2 | D23: =SUM(D8:F8) -> 63261.868 | E23: =SUM(G8:I8) -> 61147.74 | F23: =SUM(J8:L8) -> 60927.057 | G23: =SUM(M8:O8) -> 62069.03 | J23: 15/16 | K23: 2 | L23: =D23/D22-1 -> 0.0869597 | M23: =E23/E22-1 -> 0.055336064 | N23: =F23/F22-1 -> 0.029924775 | O23: =G23/G22-1 -> -0.075189764
B24: =C9 -> 16/17 | C24: 3 | D24: =SUM(D9:F9) -> 67693.036 | E24: =SUM(G9:I9) -> 71388.021 | F24: =SUM(J9:L9) -> 61623.056 | G24: =SUM(M9:O9) -> 66286.704 | J24: 16/17 | K24: 3 | L24: =D24/D23-1 -> 0.07004485 | M24: =E24/E23-1 -> 0.16746786 | N24: =F24/F23-1 -> 0.01142348 | O24: =G24/G23-1 -> 0.06795135
B25: =C10 -> 17/18 | C25: 4 | D25: =SUM(D10:F10) -> 74175.327 | E25: =SUM(G10:I10) -> 68341.424 | F25: =SUM(J10:L10) -> 71967.312 | G25: =SUM(M10:O10) -> 68362.807 | J25: 17/18 | K25: 4 | L25: =D25/D24-1 -> 0.095760096 | M25: =E25/E24-1 -> -0.042676586 | N25: =F25/F24-1 -> 0.16786341 | O25: =G25/G24-1 -> 0.031320049
B26: =C11 -> 18/19 | C26: 5 | D26: =SUM(D11:F11) -> 72227.518 | E26: =SUM(G11:I11) -> 76946.371 | F26: =SUM(J11:L11) -> 68794.113 | G26: =SUM(M11:O11) -> 76795.393 | J26: 18/19 | K26: 5 | L26: =D26/D25-1 -> -0.026259535 | M26: =E26/E25-1 -> 0.12591114 | N26: =F26/F25-1 -> -0.044092221 | O26: =G26/G25-1 -> 0.12335049
B27: =C12 -> 19/20 | C27: 6 | D27: =SUM(D12:F12) -> 72334.839 | E27: =SUM(G12:I12) -> 73002.454 | F27: =SUM(J12:L12) -> 56141.342 | G27: =SUM(M12:O12) -> 69774.502 | J27: 19/20 | K27: 6 | L27: =D27/D26-1 -> 0.0014858741 | M27: =E27/E26-1 -> -0.05125539 | N27: =F27/F26-1 -> -0.18392229 | O27: =G27/G26-1 -> -0.091423336
B28: =C13 -> 20/21 | C28: 7 | D28: =SUM(D13:F13) -> 72655.24 | E28: =SUM(G13:I13) -> 74102.777 | F28: =SUM(J13:L13) -> 80453.884 | G28: =SUM(M13:O13) -> 79786.149 | J28: 20/21 | K28: 7 | L28: =D28/D27-1 -> 0.0044294147 | M28: =E28/E27-1 -> 0.0150724 | N28: =F28/F27-1 -> 0.4330595 | O28: =G28/G27-1 -> 0.14348576
B29: =C14 -> 21/22 | C29: 8 | D29: =SUM(D14:F14) -> 86026.968 | E29: =SUM(G14:I14) -> 77599.838 | F29: =SUM(J14:L14) -> 70528.516 | G29: =SUM(M14:O14) -> 84464.192 | J29: 21/22 | K29: 8 | L29: =D29/D28-1 -> 0.18404356 | M29: =E29/E28-1 -> 0.047192048 | N29: =F29/F28-1 -> -0.12336717 | O29: =G29/G28-1 -> 0.058632272
B30: =C15 -> 22/23 | C30: 9 | D30: =SUM(D15:F15) -> 90394.97 | E30: =SUM(G15:I15) -> 86219.052 | F30: =SUM(J15:L15) -> 77589.615 | G30: =SUM(M15:O15) -> 83045.923 | J30: 22/23 | K30: 9 | L30: =D30/D29-1 -> 0.050774792 | M30: =E30/E29-1 -> 0.11107257 | N30: =F30/F29-1 -> 0.10011694 | O30: =G30/G29-1 -> -0.016791371
B31: =C16 -> 23/24 | C31: 10 | D31: =SUM(D16:F16) -> 79333.891 | E31: =SUM(G16:I16) -> 86464.578 | F31: =SUM(J16:L16) -> 95188.935 | G31: =SUM(M16:O16) -> 92296.682 | J31: 23/24 | K31: 10 | L31: =D31/D30-1 -> -0.12236388 | M31: =E31/E30-1 -> 0.0028477024 | N31: =F31/F30-1 -> 0.22682572 | O31: =G31/G30-1 -> 0.11139329
B32: =C17 -> 24/25 | C32: 11 | D32: =SUM(D17:F17) -> 75991.095 | E32: =SUM(G17:I17) -> 90505.779 | F32: =SUM(J17:L17) -> 76487.702 | G32: =SUM(M17:O17) -> 74200.812 | J32: 24/25 | K32: 11 | L32: =D32/D31-1 -> -0.042135778 | M32: =E32/E31-1 -> 0.046738228 | N32: =F32/F31-1 -> -0.19646436 | O32: =G32/G31-1 -> -0.19606198
B33: =C18 -> 25/26 | C33: 12 | D33: =SUM(D18:F18) -> 31141.41 | J33: 25/26 | K33: 12 | L33: =D33/D32-1 -> -0.59019659
D41: exports | E41: 1 | F41: 2 | G41: 3 | H41: 4 | J41: Grind
C42: 1 | D42: 17/18 | E42: =L25 -> 0.095760096 | F42: =M25 -> -0.042676586 | G42: =N25 -> 0.16786341 | H42: =O25 -> 0.031320049 | J42: 0.039868606 | K42: 0.055015438 | L42: 0.072714402 | M42: 0.027091395
C43: 2 | D43: 18/19 | E43: =L26 -> -0.026259535 | F43: =M26 -> 0.12591114 | G43: =N26 -> -0.044092221 | H43: =O26 -> 0.12335049 | J43: 0.016465413 | K43: 0.033275489 | L43: -0.031504399 | M43: -0.00050120896
C44: 3 | D44: 19/20 | E44: =L27 -> 0.0014858741 | F44: =M27 -> -0.05125539 | G44: =N27 -> -0.18392229 | H44: =O27 -> -0.091423336 | J44: -0.010865963 | K44: -0.0038476181 | L44: -0.089251645 | M44: -0.047418306
C45: 4 | D45: 20/21 | E45: =L28 -> 0.0044294147 | F45: =M28 -> 0.0150724 | G45: =N28 -> 0.4330595 | H45: =O28 -> 0.14348576 | J45: -0.031109147 | K45: -0.030138182 | L45: 0.13608695 | M45: 0.087007202
C46: 5 | D46: 21/22 | E46: =L29 -> 0.18404356 | F46: =M29 -> 0.047192048 | G46: =N29 -> -0.12336717 | H46: =O29 -> 0.058632272 | J46: 0.062981075 | K46: 0.043829912 | L46: 0.02025198 | M46: -0.016316712
C47: 6 | D47: 22/23 | E47: =L30 -> 0.050774792 | F47: =M30 -> 0.11107257 | G47: =N30 -> 0.10011694 | H47: =O30 -> -0.016791371 | J47: -0.017081891 | K47: 0.005025462 | L47: -0.057124651 | M47: -0.0091457724
C48: 7 | D48: 23/24 | E48: =L31 -> -0.12236388 | F48: =M31 -> 0.0028477024 | G48: =N31 -> 0.22682572 | H48: =O31 -> 0.11139329 | J48: -0.02457888 | K48: -0.021546454 | L48: 0.041420635 | M48: -0.032661931
C49: 8 | D49: 24/25 | E49: =L32 -> -0.042135778 | F49: =M32 -> 0.046738228 | G49: =N32 -> -0.19646436 | H49: =O32 -> -0.19606198 | J49: -0.053846307 | K49: -0.037477504 | L49: -0.071999597 | M49: -0.04792371
D50: 25/26
G54: Exports | H54: Grind
E55: 1 | F55: 1 | G55: =INDEX($E$42:$H$49,MATCH(E55,$C$42:$C$49),MATCH(F55,$E$41:$H$41)) -> 0.095760096 | H55: =INDEX($J$42:$M$49,MATCH(E55,$C$42:$C$49),MATCH(F55,$E$41:$H$41)) -> 0.039868606
E56: 1 | F56: 2 | G56: =INDEX($E$42:$H$49,MATCH(E56,$C$42:$C$49),MATCH(F56,$E$41:$H$41)) -> -0.042676586 | H56: =INDEX($J$42:$M$49,MATCH(E56,$C$42:$C$49),MATCH(F56,$E$41:$H$41)) -> 0.055015438
E57: 1 | F57: 3 | G57: =INDEX($E$42:$H$49,MATCH(E57,$C$42:$C$49),MATCH(F57,$E$41:$H$41)) -> 0.16786341 | H57: =INDEX($J$42:$M$49,MATCH(E57,$C$42:$C$49),MATCH(F57,$E$41:$H$41)) -> 0.072714402
...

Sheet Total Scenario
A1: All Reported Grind : ECA + CAA + NCA + IVC (Gepex) + BR
AD3: =COUNT(V16:Y16) -> 4 | AE3: =OFFSET(U6,0,$AD$3,1,1) -> Q4
V5: 1 | W5: 2 | X5: 3 | Y5: 4
B6: Quarter | C6: Total | D6: ECA | E6: CAA | F6: NCA | G6: IVC | H6: BR | V6: Q1 | W6: Q2 | X6: Q3 | Y6: Q4 | Z6: Q1-Q4 | AA6: % | AD6: Crop Year | AE6: =_xlfn.CONCAT("YTD (Q1 to ",AE3,")") -> YTD (Q1 to Q4) | AF6: % | AJ6: Q1 | AK6: Q2 | AL6: Q3 | AM6: Q4
B7: Q1 | 16/17 | C7: =SUM(D7:H7) -> 822589 | D7: =IF(ECA!C7=0,NA(),ECA!C7) -> 339741 | E7: =IF(CAA!C7=0,NA(),CAA!C7) -> 177450 | F7: =IF(NCA!C7=0,NA(),NCA!C7) -> 120152 | G7: =IF(IVC!C7=0,NA(),IVC!C7) -> 127000 | H7: =IF(BR!C7=0,NA(),BR!C7) -> 58246 | U7: 16/17 | V7: =C7 -> 822589 | W7: =C8 -> 822589 | X7: =C9 -> 798014 | Y7: =C10 -> 850839 | Z7: =SUM(V7:Y7) -> 3294031 | AD7: 16/17 | AE7: =SUM(OFFSET(V7,0,0,1,$AD$3)) -> 3294031 | AI7: 2017 | AJ7: =V7 -> 822589 | AK7: =AJ7+W7 -> 1645178 | AL7: =AK7+X7 -> 2443192 | AM7: =AL7+Y7 -> 3294031
B8: Q2 | 16/17 | C8: =SUM(D8:H8) -> 822589 | D8: =IF(ECA!C8=0,NA(),ECA!C8) -> 339741 | E8: =IF(CAA!C8=0,NA(),CAA!C8) -> 177450 | F8: =IF(NCA!C8=0,NA(),NCA!C8) -> 120152 | G8: =IF(IVC!C8=0,NA(),IVC!C8) -> 127000 | H8: =IF(BR!C8=0,NA(),BR!C8) -> 58246 | U8: 17/18 | V8: =C11 -> 850107 | W8: =C12 -> 855759 | X8: =C13 -> 837530 | Y8: =C14 -> 874536 | Z8: =SUM(V8:Y8) -> 3417932 | AA8: =Z8/Z7-1 -> 0.037613793 | AD8: 17/18 | AE8: =SUM(OFFSET(V8,0,0,1,$AD$3)) -> 3417932 | AF8: =AE8/AE7-1 -> 0.037613793 | AI8: 2018 | AJ8: =V8 -> 850107 | AK8: =AJ8+W8 -> 1705866 | AL8: =AK8+X8 -> 2543396 | AM8: =AL8+Y8 -> 3417932
B9: Q3 | 16/17 | C9: =SUM(D9:H9) -> 798014 | D9: =IF(ECA!C9=0,NA(),ECA!C9) -> 331970 | E9: =IF(CAA!C9=0,NA(),CAA!C9) -> 160878 | F9: =IF(NCA!C9=0,NA(),NCA!C9) -> 123125 | G9: =IF(IVC!C9=0,NA(),IVC!C9) -> 127000 | H9: =IF(BR!C9=0,NA(),BR!C9) -> 55041 | U9: 18/19 | V9: =C15 -> 881322 | W9: =C16 -> 890013 | X9: =C17 -> 882822 | Y9: =C18 -> 910769 | Z9: =SUM(V9:Y9) -> 3564926 | AA9: =Z9/Z8-1 -> 0.043006707 | AD9: 18/19 | AE9: =SUM(OFFSET(V9,0,0,1,$AD$3)) -> 3564926 | AF9: =AE9/AE8-1 -> 0.043006707 | AI9: 2019 | AJ9: =V9 -> 881322 | AK9: =AJ9+W9 -> 1771335 | AL9: =AK9+X9 -> 2654157 | AM9: =AL9+Y9 -> 3564926
B10: Q4 | 16/17 | C10: =SUM(D10:H10) -> 850839 | D10: =IF(ECA!C10=0,NA(),ECA!C10) -> 353544 | E10: =IF(CAA!C10=0,NA(),CAA!C10) -> 189407 | F10: =IF(NCA!C10=0,NA(),NCA!C10) -> 125323 | G10: =IF(IVC!C10=0,NA(),IVC!C10) -> 128000 | H10: =IF(BR!C10=0,NA(),BR!C10) -> 54565 | U10: 19/20 | V10: =C19 -> 894393 | W10: =C20 -> 891865 | X10: =C21 -> 812601 | Y10: =C22 -> 860903 | Z10: =SUM(V10:Y10) -> 3459762 | AA10: =Z10/Z9-1 -> -0.029499631 | AD10: 19/20 | AE10: =SUM(OFFSET(V10,0,0,1,$AD$3)) -> 3459762 | AF10: =AE10/AE9-1 -> -0.029499631 | AI10: 2020 | AJ10: =V10 -> 894393 | AK10: =AJ10+W10 -> 1786258 | AL10: =AK10+X10 -> 2598859 | AM10: =AL10+Y10 -> 3459762
B11: Q1 | 17/18 | C11: =SUM(D11:H11) -> 850107 | D11: =IF(ECA!C11=0,NA(),ECA!C11) -> 353286 | E11: =IF(CAA!C11=0,NA(),CAA!C11) -> 196476 | F11: =IF(NCA!C11=0,NA(),NCA!C11) -> 116080 | G11: =IF(IVC!C11=0,NA(),IVC!C11) -> 124000 | H11: =IF(BR!C11=0,NA(),BR!C11) -> 60265 | U11: 20/21 | V11: =C23 -> 890571 | W11: =C24 -> 900134 | X11: =C25 -> 865508 | Y11: =C26 -> 920397 | Z11: =SUM(V11:Y11) -> 3576610 | AA11: =Z11/Z10-1 -> 0.033773421 | AD11: 20/21 | AE11: =SUM(OFFSET(V11,0,0,1,$AD$3)) -> 3576610 | AF11: =AE11/AE10-1 -> 0.033773421 | AI11: 2021 | AJ11: =V11 -> 890571 | AK11: =AJ11+W11 -> 1790705 | AL11: =AK11+X11 -> 2656213 | AM11: =AL11+Y11 -> 3576610
